Workbook
Name LISTA_UNIDADES: CONFIGURACOES!$B$10:$B$16
Name LISTA_STATUS: CONFIGURACOES!$D$10:$D$12
Name LISTA_MEDICOES: CONFIGURACOES!$G$10:$G$33
Name LISTA_ITENS_CATALOGO: CONFIGURACOES!$B$37:$B$42

Sheet LEIA-ME
A1: SISTEMA DE CONTROLE E RELATORIO DE MEDICOES - LEIA-ME
B3: COMO USAR
B4: 1. Cadastre itens novos no catalogo (aba CONFIGURACOES, tabela a partir da linha 36) se necessario.
B5: 2. Lance medicoes na aba HISTORICO (digite direto na tabela) ou use a aba CADASTRO como formulario-guia e depois copie a linha de previa para a proxima linha livre do HISTORICO.
B6: 3. Para pesquisar, use a aba PESQUISA (por CT/texto breve ou por ITEM).
B7: 4. Para gerar o relatorio, va na aba RELATORIO_MEDICAO e escolha a NOTA e a MEDICAO nas celulas amarelas (C5 e F5). O relatorio e montado automaticamente.
B8: 5. Para imprimir: Ctrl+P na aba RELATORIO_MEDICAO (area de impressao ja configurada, A4, cabecalho repetido em todas as paginas).
B10: SOBRE O MOTOR DE CALCULO (formulas, sem macros)
B11: O sistema funciona 100% por formulas nativas do Excel (INDEX/MATCH/SUMIF/SUMIFS/COUNTIFS), sem macros, para maxima compatibilidade. A aba MOTOR_RELATORIO (oculta) extrai as linhas do HISTORICO referentes a NOTA+MEDICAO selecionadas e calcula agrupamento por ITEM (bloco), posicao da forma dentro do bloco e resultado/valor total de cada bloco.
B12: O RELATORIO_MEDICAO suporta ate 20 itens por medicao e ate 6 formas/medicoes por item (muito acima do exemplo do PDF de referencia, que tem 6 itens e no maximo 3 formas). Linhas de capacidade nao usadas ficam em branco e podem ser recolhidas (agrupamento/outline a esquerda da planilha).
B14: REGRA DE X, Y, Z (nao inverter)
B15: Na aba HISTORICO, por especificacao, a coluna O guarda Z, a coluna P guarda Y e a coluna Q guarda X. O RESULTADO = QUANTIDADE x X x Y x Z (campos vazios contam como 1). O relatorio exibe sempre na ordem visual X | Y | Z.
B17: MODULOS VBA OPCIONAIS (pasta /medicoes/vba)
... B21: A aba HISTORICO ja contem 8 lancamentos de teste (NOTA 29655103, MEDICAO 1), extraidos do PDF de referencia ENG003341, formando os 6 blocos/itens do documento. TOTAL GERAL esperado: R$ 2.469,77. Apague ou edite esses lancamentos quando for usar o sistema com dados reais.

Sheet CADASTRO
A1: CADASTRO / LANCAMENTO DE MEDICAO
A2: Preencha os campos abaixo. LINHA, ATIVIDADE, UND. e PRECO UNITARIO sao preenchidos automaticamente ao escolher o ITEM (base: aba CONFIGURACOES). RESULTADO e VALOR TOTAL sao calculados automaticamente nesta previa. Depois, copie a linha de previa para a proxima linha livre da tabela da aba HISTORICO - ou digite direto la, que tem as mesmas formulas - ou use o botao ADICIONAR AO HISTORICO apos importar o VBA opcional.
B6: DADOS DA MEDICAO
B7: NOTA:
B8: T.MED:
B9: MEDICAO:
B10: ELAB.:
B11: OBRA:
B12: FISCAL:
B13: CT:
B14: SUPER.:
B15: DATA:
B16: ITEM DA MEDICAO
B17: ITEM:
B18: LINHA (auto): | C18: =IFERROR(INDEX(CONFIGURACOES!$G$37:$G$300,MATCH($C$17,CONFIGURACOES!$B$37:$B$300,0)),"")
B19: ATIVIDADE (auto): | C19: =IFERROR(INDEX(CONFIGURACOES!$H$37:$H$300,MATCH($C$17,CONFIGURACOES!$B$37:$B$300,0)),"")
B20: DESCRICAO (forma):
B21: UND. (auto/editavel): | C21: =IFERROR(INDEX(CONFIGURACOES!$I$37:$I$300,MATCH($C$17,CONFIGURACOES!$B$37:$B$300,0)),"")
B22: QUANTIDADE:
B23: X:
B24: Y:
B25: Z:
B26: VALORES / STATUS
B27: PRECO UNITARIO (auto/editavel): | C27: =IFERROR(INDEX(CONFIGURACOES!$J$37:$J$300,MATCH($C$17,CONFIGURACOES!$B$37:$B$300,0)),"")
B28: STATUS:
B30: RESULTADO (previa): | C30: =IF($C$22="","",$C$22*IF($C$23="",1,$C$23)*IF($C$24="",1,$C$24)*IF($C$25="",1,$C$25))
B31: VALOR TOTAL (previa): | C31: =IF(OR($C$30="",$C$27=""),"",$C$30*$C$27)
B33: Campos obrigatorios: NOTA, T.MED, MEDICAO, OBRA, DATA, ITEM. Numericos: QUANTIDADE, X, Y, Z, PRECO UNITARIO. O RESULTADO nunca deve ser digitado manualmente.
B35: + ADICIONAR AO HISTORICO
B36: Este botao e visual. Para ativa-lo: importe os modulos VBA (pasta /medicoes/vba, veja o README) e depois clique com o botao direito aqui -> Atribuir Macro -> AdicionarLancamento.

Sheet HISTORICO
A1: HISTORICO DE MEDICOES (tabela mestre - cresce automaticamente)
A2: NOTA | B2: T.MED | C2: MEDICAO | D2: ELAB. | E2: OBRA | F2: FISCAL | G2: CT | H2: SUPER. | I2: ITEM | J2: LINHA | K2: ATIVIDADE | L2: DESCRICAO | M2: UND. | N2: QUANTIDADE | O2: Z | P2: Y | Q2: X | R2: RESULTADO | S2: PRECO UNITARIO | T2: VALOR TOTAL | U2: DATA | V2: APROVADO | W2: DESCRICAO DO STATUS | X2: [aux] CHAVE_GRUPO | Y2: [aux] RANKSEL_RELATORIO | Z2: [aux] FLAG_CT | AA2: [aux] RANK_CT | AB2: [aux] FLAG_ITEM | AC2: [aux] RANK_ITEM
A3: 29655103 | B3: MED | C3: 1 | D3: Mariana Dalapicola | E3: CAPL/LLE/ PISO INSTALACAO NOVA BOMBA | F3: ORYANE | G3: S31C-MIL | H3: - | I3: 19.12.4 | J3: =IFERROR(INDEX(CONFIGURACOES!$G$37:$G$300,MATCH($I3,CONFIGURACOES!$B$37:$B$300,0)),"") | K3: =IFERROR(INDEX(CONFIGURACOES!$H$37:$H$300,MATCH($I3,CONFIGURACOES!$B$37:$B$300,0)),"") | L3: Rastreamento | M3: =IFERROR(INDEX(CONFIGURACOES!$I$37:$I$300,MATCH($I3,CONFIGURACOES!$B$37:$B$300,0)),"") | N3: 1 | O3: 1 | P3: 1 | Q3: 2 | R3: =IF($N3="","",$N3*IF($Q3="",1,$Q3)*IF($P3="",1,$P3)*IF($O3="",1,$O3)) | S3: =IFERROR(INDEX(CONFIGURACOES!$J$37:$J$300,MATCH($I3,CONFIGURACOES!$B$37:$B$300,0)),"") | T3: =IF(OR($R3="",$S3=""),"",$R3*$S3) | U3: 2026-09-02 | V3: Pendente | W3: Medicao de teste extraida do PDF de referencia ENG003341 (NOTA 29655103). | X3: =IF($A3="","",$A3&"|"&$C3&"|"&$I3) | Y3: =IF(AND($A3=RELATORIO_MEDICAO!$C$5,$C3=RELATORIO_MEDICAO!$F$5,$A3<>""),COUNTIFS($A$3:$A3,RELATORIO_MEDICAO!$C$5,$C$3:$C3,RELATORIO_MEDICAO!$F$5),"") | Z3: =IF(OR($A3="",PESQUISA!$C$4=""),0,IF(OR(ISNUMBER(SEARCH(PESQUISA!$C$4,$G3)),ISNUMBER(SEARCH(PESQUISA!$C$4,$K3)),ISNUMBER(SEARCH(PESQUISA!$C$4,$L3))),1,0)) | AA3: =IF($Z3=1,SUM($Z$3:$Z3),"") | AB3: =IF(OR($A3="",PESQUISA!$C$50=""),0,IF(ISNUMBER(SEARCH(PESQUISA!$C$50,$I3)),1,0)) | AC3: =IF($AB3=1,SUM($AB$3:$AB3),"")
A4: 29655103 | B4: MED | C4: 1 | D4: Mariana Dalapicola | E4: CAPL/LLE/ PISO INSTALACAO NOVA BOMBA | F4: ORYANE | G4: S31C-MIL | H4: - | I4: 19.1.2 | J4: =IFERROR(INDEX(CONFIGURACOES!$G$37:$G$300,MATCH($I4,CONFIGURACOES!$B$37:$B$300,0)),"") | K4: =IFERROR(INDEX(CONFIGURACOES!$H$37:$H$300,MATCH($I4,CONFIGURACOES!$B$37:$B$300,0)),"") | L4: Demolicao | M4: =IFERROR(INDEX(CONFIGURACOES!$I$37:$I$300,MATCH($I4,CONFIGURACOES!$B$37:$B$300,0)),"") | N4: 1 | O4: 0.06 | P4: 1.5 | Q4: 1.05 | R4: =IF($N4="","",$N4*IF($Q4="",1,$Q4)*IF($P4="",1,$P4)*IF($O4="",1,$O4)) | S4: =IFERROR(INDEX(CONFIGURACOES!$J$37:$J$300,MATCH($I4,CONFIGURACOES!$B$37:$B$300,0)),"") | T4: =IF(OR($R4="",$S4=""),"",$R4*$S4) | U4: 2026-09-02 | V4: Pendente | W4: Medicao de teste extraida do PDF de referencia ENG003341 (NOTA 29655103). | X4: =IF($A4="","",$A4&"|"&$C4&"|"&$I4) | Y4: =IF(AND($A4=RELATORIO_MEDICAO!$C$5,$C4=RELATORIO_MEDICAO!$F$5,$A4<>""),COUNTIFS($A$3:$A4,RELATORIO_MEDICAO!$C$5,$C$3:$C4,RELATORIO_MEDICAO!$F$5),"") | Z4: =IF(OR($A4="",PESQUISA!$C$4=""),0,IF(OR(ISNUMBER(SEARCH(PESQUISA!$C$4,$G4)),ISNUMBER(SEARCH(PESQUISA!$C$4,$K4)),ISNUMBER(SEARCH(PESQUISA!$C$4,$L4))),1,0)) | AA4: =IF($Z4=1,SUM($Z$3:$Z4),"") | AB4: =IF(OR($A4="",PESQUISA!$C$50=""),0,IF(ISNUMBER(SEARCH(PESQUISA!$C$50,$I4)),1,0)) | AC4: =IF($AB4=1,SUM($AB$3:$AB4),"")
A5: 29655103 | B5: MED | C5: 1 | D5: Mariana Dalapicola | E5: CAPL/LLE/ PISO INSTALACAO NOVA BOMBA | F5: ORYANE | G5: S31C-MIL | H5: - | I5: 3.1.1 | J5: =IFERROR(INDEX(CONFIGURACOES!$G$37:$G$300,MATCH($I5,CONFIGURACOES!$B$37:$B$300,0)),"") | K5: =IFERROR(INDEX(CONFIGURACOES!$H$37:$H$300,MATCH($I5,CONFIGURACOES!$B$37:$B$300,0)),"") | L5: Forma 1 | M5: =IFERROR(INDEX(CONFIGURACOES!$I$37:$I$300,MATCH($I5,CONFIGURACOES!$B$37:$B$300,0)),"") | N5: 1 | O5: 1 | P5: 0.35 | Q5: 1.05 | R5: =IF($N5="","",$N5*IF($Q5="",1,$Q5)*IF($P5="",1,$P5)*IF($O5="",1,$O5)) | S5: =IFERROR(INDEX(CONFIGURACOES!$J$37:$J$300,MATCH($I5,CONFIGURACOES!$B$37:$B$300,0)),"") | T5: =IF(OR($R5="",$S5=""),"",$R5*$S5) | U5: 2026-09-02 | V5: Pendente | W5: Medicao de teste extraida do PDF de referencia ENG003341 (NOTA 29655103). | X5: =IF($A5="","",$A5&"|"&$C5&"|"&$I5) | Y5: =IF(AND($A5=RELATORIO_MEDICAO!$C$5,$C5=RELATORIO_MEDICAO!$F$5,$A5<>""),COUNTIFS($A$3:$A5,RELATORIO_MEDICAO!$C$5,$C$3:$C5,RELATORIO_MEDICAO!$F$5),"") | Z5: =IF(OR($A5="",PESQUISA!$C$4=""),0,IF(OR(ISNUMBER(SEARCH(PESQUISA!$C$4,$G5)),ISNUMBER(SEARCH(PESQUISA!$C$4,$K5)),ISNUMBER(SEARCH(PESQUISA!$C$4,$L5))),1,0)) | AA5: =IF($Z5=1,SUM($Z$3:$Z5),"") | AB5: =IF(OR($A5="",PESQUISA!$C$50=""),0,IF(ISNUMBER(SEARCH(PESQUISA!$C$50,$I5)),1,0)) | AC5: =IF($AB5=1,SUM($AB$3:$AB5),"")
A6: 29655103 | B6: MED | C6: 1 | D6: Mariana Dalapicola | E6: CAPL/LLE/ PISO INSTALACAO NOVA BOMBA | F6: ORYANE | G6: S31C-MIL | H6: - | I6: 3.1.1 | J6: =IFERROR(INDEX(CONFIGURACOES!$G$37:$G$300,MATCH($I6,CONFIGURACOES!$B$37:$B$300,0)),"") | K6: =IFERROR(INDEX(CONFIGURACOES!$H$37:$H$300,MATCH($I6,CONFIGURACOES!$B$37:$B$300,0)),"") | L6: Forma 2 | M6: =IFERROR(INDEX(CONFIGURACOES!$I$37:$I$300,MATCH($I6,CONFIGURACOES!$B$37:$B$300,0)),"") | N6: 2 | O6: 1 | P6: 0.06 | Q6: 1.05 | R6: =IF($N6="","",$N6*IF($Q6="",1,$Q6)*IF($P6="",1,$P6)*IF($O6="",1,$O6)) | S6: =IFERROR(INDEX(CONFIGURACOES!$J$37:$J$300,MATCH($I6,CONFIGURACOES!$B$37:$B$300,0)),"") | T6: =IF(OR($R6="",$S6=""),"",$R6*$S6) | U6: 2026-09-02 | V6: Pendente | W6: Medicao de teste extraida do PDF de referencia ENG003341 (NOTA 29655103). | X6: =IF($A6="","",$A6&"|"&$C6&"|"&$I6) | Y6: =IF(AND($A6=RELATORIO_MEDICAO!$C$5,$C6=RELATORIO_MEDICAO!$F$5,$A6<>""),COUNTIFS($A$3:$A6,RELATORIO_MEDICAO!$C$5,$C$3:$C6,RELATORIO_MEDICAO!$F$5),"") | Z6: =IF(OR($A6="",PESQUISA!$C$4=""),0,IF(OR(ISNUMBER(SEARCH(PESQUISA!$C$4,$G6)),ISNUMBER(SEARCH(PESQUISA!$C$4,$K6)),ISNUMBER(SEARCH(PESQUISA!$C$4,$L6))),1,0)) | AA6: =IF($Z6=1,SUM($Z$3:$Z6),"") | AB6: =IF(OR($A6="",PESQUISA!$C$50=""),0,IF(ISNUMBER(SEARCH(PESQUISA!$C$50,$I6)),1,0)) | AC6: =IF($AB6=1,SUM($AB$3:$AB6),"")
A7: 29655103 | B7: MED | C7: 1 | D7: Mariana Dalapicola | E7: CAPL/LLE/ PISO INSTALACAO NOVA BOMBA | F7: ORYANE | G7: S31C-MIL | H7: - | I7: 3.1.1 | J7: =IFERROR(INDEX(CONFIGURACOES!$G$37:$G$300,MATCH($I7,CONFIGURACOES!$B$37:$B$300,0)),"") | K7: =IFERROR(INDEX(CONFIGURACOES!$H$37:$H$300,MATCH($I7,CONFIGURACOES!$B$37:$B$300,0)),"") | L7: Forma 3 | M7: =IFERROR(INDEX(CONFIGURACOES!$I$37:$I$300,MATCH($I7,CONFIGURACOES!$B$37:$B$300,0)),"") | N7: 2 | O7: 1 | P7: 0.06 | Q7: 1.5 | R7: =IF($N7="","",$N7*IF($Q7="",1,$Q7)*IF($P7="",1,$P7)*IF($O7="",1,$O7)) | S7: =IFERROR(INDEX(CONFIGURACOES!$J$37:$J$300,MATCH($I7,CONFIGURACOES!$B$37:$B$300,0)),"") | T7: =IF(OR($R7="",$S7=""),"",$R7*$S7) | U7: 2026-09-02 | V7: Pendente | W7: Medicao de teste extraida do PDF de referencia ENG003341 (NOTA 29655103). | X7: =IF($A7="","",$A7&"|"&$C7&"|"&$I7) | Y7: =IF(AND($A7=RELATORIO_MEDICAO!$C$5,$C7=RELATORIO_MEDICAO!$F$5,$A7<>""),COUNTIFS($A$3:$A7,RELATORIO_MEDICAO!$C$5,$C$3:$C7,RELATORIO_MEDICAO!$F$5),"") | Z7: =IF(OR($A7="",PESQUISA!$C$4=""),0,IF(OR(ISNUMBER(SEARCH(PESQUISA!$C$4,$G7)),ISNUMBER(SEARCH(PESQUISA!$C$4,$K7)),ISNUMBER(SEARCH(PESQUISA!$C$4,$L7))),1,0)) | AA7: =IF($Z7=1,SUM($Z$3:$Z7),"") | AB7: =IF(OR($A7="",PESQUISA!$C$50=""),0,IF(ISNUMBER(SEARCH(PESQUISA!$C$50,$I7)),1,0)) | AC7: =IF($AB7=1,SUM($AB$3:$AB7),"")
A8: 29655103 | B8: MED | C8: 1 | D8: Mariana Dalapicola | E8: CAPL/LLE/ PISO INSTALACAO NOVA BOMBA | F8: ORYANE | G8: S31C-MIL | H8: - | I8: 4.1.4 | J8: =IFERROR(INDEX(CONFIGURACOES!$G$37:$G$300,MATCH($I8,CONFIGURACOES!$B$37:$B$300,0)),"") | K8: =IFERROR(INDEX(CONFIGURACOES!$H$37:$H$300,MATCH($I8,CONFIGURACOES!$B$37:$B$300,0)),"") | L8: Malha | M8: =IFERROR(INDEX(CONFIGURACOES!$I$37:$I$300,MATCH($I8,CONFIGURACOES!$B$37:$B$300,0)),"") | N8: 1 | O8: 1.48 | P8: 1.05 | Q8: 1.5 | R8: =IF($N8="","",$N8*IF($Q8="",1,$Q8)*IF($P8="",1,$P8)*IF($O8="",1,$O8)) | S8: =IFERROR(INDEX(CONFIGURACOES!$J$37:$J$300,MATCH($I8,CONFIGURACOES!$B$37:$B$300,0)),"") | T8: =IF(OR($R8="",$S8=""),"",$R8*$S8) | U8: 2026-09-02 | V8: Pendente | W8: Medicao de teste extraida do PDF de referencia ENG003341 (NOTA 29655103). | X8: =IF($A8="","",$A8&"|"&$C8&"|"&$I8) | Y8: =IF(AND($A8=RELATORIO_MEDICAO!$C$5,$C8=RELATORIO_MEDICAO!$F$5,$A8<>""),COUNTIFS($A$3:$A8,RELATORIO_MEDICAO!$C$5,$C$3:$C8,RELATORIO_MEDICAO!$F$5),"") | Z8: =IF(OR($A8="",PESQUISA!$C$4=""),0,IF(OR(ISNUMBER(SEARCH(PESQUISA!$C$4,$G8)),ISNUMBER(SEARCH(PESQUISA!$C$4,$K8)),ISNUMBER(SEARCH(PESQUISA!$C$4,$L8))),1,0)) | AA8: =IF($Z8=1,SUM($Z$3:$Z8),"") | AB8: =IF(OR($A8="",PESQUISA!$C$50=""),0,IF(ISNUMBER(SEARCH(PESQUISA!$C$50,$I8)),1,0)) | AC8: =IF($AB8=1,SUM($AB$3:$AB8),"")
A9: 29655103 | B9: MED | C9: 1 | D9: Mariana Dalapicola | E9: CAPL/LLE/ PISO INSTALACAO NOVA BOMBA | F9: ORYANE | G9: S31C-MIL | H9: - | I9: 6.3 | J9: =IFERROR(INDEX(CONFIGURACOES!$G$37:$G$300,MATCH($I9,CONFIGURACOES!$B$37:$B$300,0)),"") | K9: =IFERROR(INDEX(CONFIGURACOES!$H$37:$H$300,MATCH($I9,CONFIGURACOES!$B$37:$B$300,0)),"") | L9: Graute | M9: =IFERROR(INDEX(CONFIGURACOES!$I$37:$I$300,MATCH($I9,CONFIGURACOES!$B$37:$B$300,0)),"") | N9: 1 | O9: 1 | P9: 1 | Q9: 0.03 | R9: =IF($N9="","",$N9*IF($Q9="",1,$Q9)*IF($P9="",1,$P9)*IF($O9="",1,$O9)) | S9: =IFERROR(INDEX(CONFIGURACOES!$J$37:$J$300,MATCH($I9,CONFIGURACOES!$B$37:$B$300,0)),"") | T9: =IF(OR($R9="",$S9=""),"",$R9*$S9) | U9: 2026-09-02 | V9: Pendente | W9: Medicao de teste extraida do PDF de referencia ENG003341 (NOTA 29655103). | X9: =IF($A9="","",$A9&"|"&$C9&"|"&$I9) | Y9: =IF(AND($A9=RELATORIO_MEDICAO!$C$5,$C9=RELATORIO_MEDICAO!$F$5,$A9<>""),COUNTIFS($A$3:$A9,RELATORIO_MEDICAO!$C$5,$C$3:$C9,RELATORIO_MEDICAO!$F$5),"") | Z9: =IF(OR($A9="",PESQUISA!$C$4=""),0,IF(OR(ISNUMBER(SEARCH(PESQUISA!$C$4,$G9)),ISNUMBER(SEARCH(PESQUISA!$C$4,$K9)),ISNUMBER(SEARCH(PESQUISA!$C$4,$L9))),1,0)) | AA9: =IF($Z9=1,SUM($Z$3:$Z9),"") | AB9: =IF(OR($A9="",PESQUISA!$C$50=""),0,IF(ISNUMBER(SEARCH(PESQUISA!$C$50,$I9)),1,0)) | AC9: =IF($AB9=1,SUM($AB$3:$AB9),"")
A10: 29655103 | B10: MED | C10: 1 | D10: Mariana Dalapicola | E10: CAPL/LLE/ PISO INSTALACAO NOVA BOMBA | F10: ORYANE | G10: S31C-MIL | H10: - | I10: 7.1 | J10: =IFERROR(INDEX(CONFIGURACOES!$G$37:$G$300,MATCH($I10,CONFIGURACOES!$B$37:$B$300,0)),"") | K10: =IFERROR(INDEX(CONFIGURACOES!$H$37:$H$300,MATCH($I10,CONFIGURACOES!$B$37:$B$300,0)),"") | L10: Sikadur | M10: =IFERROR(INDEX(CONFIGURACOES!$I$37:$I$300,MATCH($I10,CONFIGURACOES!$B$37:$B$300,0)),"") | N10: 1 | O10: 1 | P10: 1 | Q10: 1 | R10: =IF($N10="","",$N10*IF($Q10="",1,$Q10)*IF($P10="",1,$P10)*IF($O10="",1,$O10)) | S10: =IFERROR(INDEX(CONFIGURACOES!$J$37:$J$300,MATCH($I10,CONFIGURACOES!$B$37:$B$300,0)),"") | T10: =IF(OR($R10="",$S10=""),"",$R10*$S10) | U10: 2026-09-02 | V10: Pendente | W10: Medicao de teste extraida do PDF de referencia ENG003341 (NOTA 29655103). | X10: =IF($A10="","",$A10&"|"&$C10&"|"&$I10) | Y10: =IF(AND($A10=RELATORIO_MEDICAO!$C$5,$C10=RELATORIO_MEDICAO!$F$5,$A10<>""),COUNTIFS($A$3:$A10,RELATORIO_MEDICAO!$C$5,$C$3:$C10,RELATORIO_MEDICAO!$F$5),"") | Z10: =IF(OR($A10="",PESQUISA!$C$4=""),0,IF(OR(ISNUMBER(SEARCH(PESQUISA!$C$4,$G10)),ISNUMBER(SEARCH(PESQUISA!$C$4,$K10)),ISNUMBER(SEARCH(PESQUISA!$C$4,$L10))),1,0)) | AA10: =IF($Z10=1,SUM($Z$3:$Z10),"") | AB10: =IF(OR($A10="",PESQUISA!$C$50=""),0,IF(ISNUMBER(SEARCH(PESQUISA!$C$50,$I10)),1,0)) | AC10: =IF($AB10=1,SUM($AB$3:$AB10),"")
J11: =IFERROR(INDEX(CONFIGURACOES!$G$37:$G$300,MATCH($I11,CONFIGURACOES!$B$37:$B$300,0)),"") | K11: =IFERROR(INDEX(CONFIGURACOES!$H$37:$H$300,MATCH($I11,CONFIGURACOES!$B$37:$B$300,0)),"") | M11: =IFERROR(INDEX(CONFIGURACOES!$I$37:$I$300,MATCH($I11,CONFIGURACOES!$B$37:$B$300,0)),"") | R11: =IF($N11="","",$N11*IF($Q11="",1,$Q11)*IF($P11="",1,$P11)*IF($O11="",1,$O11)) | S11: =IFERROR(INDEX(CONFIGURACOES!$J$37:$J$300,MATCH($I11,CONFIGURACOES!$B$37:$B$300,0)),"") | T11: =IF(OR($R11="",$S11=""),"",$R11*$S11) | X11: =IF($A11="","",$A11&"|"&$C11&"|"&$I11) | Y11: =IF(AND($A11=RELATORIO_MEDICAO!$C$5,$C11=RELATORIO_MEDICAO!$F$5,$A11<>""),COUNTIFS($A$3:$A11,RELATORIO_MEDICAO!$C$5,$C$3:$C11,RELATORIO_MEDICAO!$F$5),"") | Z11: =IF(OR($A11="",PESQUISA!$C$4=""),0,IF(OR(ISNUMBER(SEARCH(PESQUISA!$C$4,$G11)),ISNUMBER(SEARCH(PESQUISA!$C$4,$K11)),ISNUMBER(SEARCH(PESQUISA!$C$4,$L11))),1,0)) | AA11: =IF($Z11=1,SUM($Z$3:$Z11),"") | AB11: =IF(OR($A11="",PESQUISA!$C$50=""),0,IF(ISNUMBER(SEARCH(PESQUISA!$C$50,$I11)),1,0)) | AC11: =IF($AB11=1,SUM($AB$3:$AB11),"")
J12: =IFERROR(INDEX(CONFIGURACOES!$G$37:$G$300,MATCH($I12,CONFIGURACOES!$B$37:$B$300,0)),"") | K12: =IFERROR(INDEX(CONFIGURACOES!$H$37:$H$300,MATCH($I12,CONFIGURACOES!$B$37:$B$300,0)),"") | M12: =IFERROR(INDEX(CONFIGURACOES!$I$37:$I$300,MATCH($I12,CONFIGURACOES!$B$37:$B$300,0)),"") | R12: =IF($N12="","",$N12*IF($Q12="",1,$Q12)*IF($P12="",1,$P12)*IF($O12="",1,$O12)) | S12: =IFERROR(INDEX(CONFIGURACOES!$J$37:$J$300,MATCH($I12,CONFIGURACOES!$B$37:$B$300,0)),"") | T12: =IF(OR($R12="",$S12=""),"",$R12*$S12) | X12: =IF($A12="","",$A12&"|"&$C12&"|"&$I12) | Y12: =IF(AND($A12=RELATORIO_MEDICAO!$C$5,$C12=RELATORIO_MEDICAO!$F$5,$A12<>""),COUNTIFS($A$3:$A12,RELATORIO_MEDICAO!$C$5,$C$3:$C12,RELATORIO_MEDICAO!$F$5),"") | Z12: =IF(OR($A12="",PESQUISA!$C$4=""),0,IF(OR(ISNUMBER(SEARCH(PESQUISA!$C$4,$G12)),ISNUMBER(SEARCH(PESQUISA!$C$4,$K12)),ISNUMBER(SEARCH(PESQUISA!$C$4,$L12))),1,0)) | AA12: =IF($Z12=1,SUM($Z$3:$Z12),"") | AB12: =IF(OR($A12="",PESQUISA!$C$50=""),0,IF(ISNUMBER(SEARCH(PESQUISA!$C$50,$I12)),1,0)) | AC12: =IF($AB12=1,SUM($AB$3:$AB12),"")
J13: =IFERROR(INDEX(CONFIGURACOES!$G$37:$G$300,MATCH($I13,CONFIGURACOES!$B$37:$B$300,0)),"") | K13: =IFERROR(INDEX(CONFIGURACOES!$H$37:$H$300,MATCH($I13,CONFIGURACOES!$B$37:$B$300,0)),"") | M13: =IFERROR(INDEX(CONFIGURACOES!$I$37:$I$300,MATCH($I13,CONFIGURACOES!$B$37:$B$300,0)),"") | R13: =IF($N13="","",$N13*IF($Q13="",1,$Q13)*IF($P13="",1,$P13)*IF($O13="",1,$O13)) | S13: =IFERROR(INDEX(CONFIGURACOES!$J$37:$J$300,MATCH($I13,CONFIGURACOES!$B$37:$B$300,0)),"") | T13: =IF(OR($R13="",$S13=""),"",$R13*$S13) | X13: =IF($A13="","",$A13&"|"&$C13&"|"&$I13) | Y13: =IF(AND($A13=RELATORIO_MEDICAO!$C$5,$C13=RELATORIO_MEDICAO!$F$5,$A13<>""),COUNTIFS($A$3:$A13,RELATORIO_MEDICAO!$C$5,$C$3:$C13,RELATORIO_MEDICAO!$F$5),"") | Z13: =IF(OR($A13="",PESQUISA!$C$4=""),0,IF(OR(ISNUMBER(SEARCH(PESQUISA!$C$4,$G13)),ISNUMBER(SEARCH(PESQUISA!$C$4,$K13)),ISNUMBER(SEARCH(PESQUISA!$C$4,$L13))),1,0)) | AA13: =IF($Z13=1,SUM($Z$3:$Z13),"") | AB13: =IF(OR($A13="",PESQUISA!$C$50=""),0,IF(ISNUMBER(SEARCH(PESQUISA!$C$50,$I13)),1,0)) | AC13: =IF($AB13=1,SUM($AB$3:$AB13),"")
J14: =IFERROR(INDEX(CONFIGURACOES!$G$37:$G$300,MATCH($I14,CONFIGURACOES!$B$37:$B$300,0)),"") | K14: =IFERROR(INDEX(CONFIGURACOES!$H$37:$H$300,MATCH($I14,CONFIGURACOES!$B$37:$B$300,0)),"") | M14: =IFERROR(INDEX(CONFIGURACOES!$I$37:$I$300,MATCH($I14,CONFIGURACOES!$B$37:$B$300,0)),"") | R14: =IF($N14="","",$N14*IF($Q14="",1,$Q14)*IF($P14="",1,$P14)*IF($O14="",1,$O14)) | S14: =IFERROR(INDEX(CONFIGURACOES!$J$37:$J$300,MATCH($I14,CONFIGURACOES!$B$37:$B$300,0)),"") | T14: =IF(OR($R14="",$S14=""),"",$R14*$S14) | X14: =IF($A14="","",$A14&"|"&$C14&"|"&$I14) | Y14: =IF(AND($A14=RELATORIO_MEDICAO!$C$5,$C14=RELATORIO_MEDICAO!$F$5,$A14<>""),COUNTIFS($A$3:$A14,RELATORIO_MEDICAO!$C$5,$C$3:$C14,RELATORIO_MEDICAO!$F$5),"") | Z14: =IF(OR($A14="",PESQUISA!$C$4=""),0,IF(OR(ISNUMBER(SEARCH(PESQUISA!$C$4,$G14)),ISNUMBER(SEARCH(PESQUISA!$C$4,$K14)),ISNUMBER(SEARCH(PESQUISA!$C$4,$L14))),1,0)) | AA14: =IF($Z14=1,SUM($Z$3:$Z14),"") | AB14: =IF(OR($A14="",PESQUISA!$C$50=""),0,IF(ISNUMBER(SEARCH(PESQUISA!$C$50,$I14)),1,0)) | AC14: =IF($AB14=1,SUM($AB$3:$AB14),"")
J15: =IFERROR(INDEX(CONFIGURACOES!$G$37:$G$300,MATCH($I15,CONFIGURACOES!$B$37:$B$300,0)),"") | K15: =IFERROR(INDEX(CONFIGURACOES!$H$37:$H$300,MATCH($I15,CONFIGURACOES!$B$37:$B$300,0)),"") | M15: =IFERROR(INDEX(CONFIGURACOES!$I$37:$I$300,MATCH($I15,CONFIGURACOES!$B$37:$B$300,0)),"") | R15: =IF($N15="","",$N15*IF($Q15="",1,$Q15)*IF($P15="",1,$P15)*IF($O15="",1,$O15)) | S15: =IFERROR(INDEX(CONFIGURACOES!$J$37:$J$300,MATCH($I15,CONFIGURACOES!$B$37:$B$300,0)),"") | T15: =IF(OR($R15="",$S15=""),"",$R15*$S15) | X15: =IF($A15="","",$A15&"|"&$C15&"|"&$I15) | Y15: =IF(AND($A15=RELATORIO_MEDICAO!$C$5,$C15=RELATORIO_MEDICAO!$F$5,$A15<>""),COUNTIFS($A$3:$A15,RELATORIO_MEDICAO!$C$5,$C$3:$C15,RELATORIO_MEDICAO!$F$5),"") | Z15: =IF(OR($A15="",PESQUISA!$C$4=""),0,IF(OR(ISNUMBER(SEARCH(PESQUISA!$C$4,$G15)),ISNUMBER(SEARCH(PESQUISA!$C$4,$K15)),ISNUMBER(SEARCH(PESQUISA!$C$4,$L15))),1,0)) | AA15: =IF($Z15=1,SUM($Z$3:$Z15),"") | AB15: =IF(OR($A15="",PESQUISA!$C$50=""),0,IF(ISNUMBER(SEARCH(PESQUISA!$C$50,$I15)),1,0)) | AC15: =IF($AB15=1,SUM($AB$3:$AB15),"")
J16: =IFERROR(INDEX(CONFIGURACOES!$G$37:$G$300,MATCH($I16,CONFIGURACOES!$B$37:$B$300,0)),"") | K16: =IFERROR(INDEX(CONFIGURACOES!$H$37:$H$300,MATCH($I16,CONFIGURACOES!$B$37:$B$300,0)),"") | M16: =IFERROR(INDEX(CONFIGURACOES!$I$37:$I$300,MATCH($I16,CONFIGURACOES!$B$37:$B$300,0)),"") | R16: =IF($N16="","",$N16*IF($Q16="",1,$Q16)*IF($P16="",1,$P16)*IF($O16="",1,$O16)) | S16: =IFERROR(INDEX(CONFIGURACOES!$J$37:$J$300,MATCH($I16,CONFIGURACOES!$B$37:$B$300,0)),"") | T16: =IF(OR($R16="",$S16=""),"",$R16*$S16) | X16: =IF($A16="","",$A16&"|"&$C16&"|"&$I16) | Y16: =IF(AND($A16=RELATORIO_MEDICAO!$C$5,$C16=RELATORIO_MEDICAO!$F$5,$A16<>""),COUNTIFS($A$3:$A16,RELATORIO_MEDICAO!$C$5,$C$3:$C16,RELATORIO_MEDICAO!$F$5),"") | Z16: =IF(OR($A16="",PESQUISA!$C$4=""),0,IF(OR(ISNUMBER(SEARCH(PESQUISA!$C$4,$G16)),ISNUMBER(SEARCH(PESQUISA!$C$4,$K16)),ISNUMBER(SEARCH(PESQUISA!$C$4,$L16))),1,0)) | AA16: =IF($Z16=1,SUM($Z$3:$Z16),"") | AB16: =IF(OR($A16="",PESQUISA!$C$50=""),0,IF(ISNUMBER(SEARCH(PESQUISA!$C$50,$I16)),1,0)) | AC16: =IF($AB16=1,SUM($AB$3:$AB16),"")
J17: =IFERROR(INDEX(CONFIGURACOES!$G$37:$G$300,MATCH($I17,CONFIGURACOES!$B$37:$B$300,0)),"") | K17: =IFERROR(INDEX(CONFIGURACOES!$H$37:$H$300,MATCH($I17,CONFIGURACOES!$B$37:$B$300,0)),"") | M17: =IFERROR(INDEX(CONFIGURACOES!$I$37:$I$300,MATCH($I17,CONFIGURACOES!$B$37:$B$300,0)),"") | R17: =IF($N17="","",$N17*IF($Q17="",1,$Q17)*IF($P17="",1,$P17)*IF($O17="",1,$O17)) | S17: =IFERROR(INDEX(CONFIGURACOES!$J$37:$J$300,MATCH($I17,CONFIGURACOES!$B$37:$B$300,0)),"") | T17: =IF(OR($R17="",$S17=""),"",$R17*$S17) | X17: =IF($A17="","",$A17&"|"&$C17&"|"&$I17) | Y17: =IF(AND($A17=RELATORIO_MEDICAO!$C$5,$C17=RELATORIO_MEDICAO!$F$5,$A17<>""),COUNTIFS($A$3:$A17,RELATORIO_MEDICAO!$C$5,$C$3:$C17,RELATORIO_MEDICAO!$F$5),"") | Z17: =IF(OR($A17="",PESQUISA!$C$4=""),0,IF(OR(ISNUMBER(SEARCH(PESQUISA!$C$4,$G17)),ISNUMBER(SEARCH(PESQUISA!$C$4,$K17)),ISNUMBER(SEARCH(PESQUISA!$C$4,$L17))),1,0)) | AA17: =IF($Z17=1,SUM($Z$3:$Z17),"") | AB17: =IF(OR($A17="",PESQUISA!$C$50=""),0,IF(ISNUMBER(SEARCH(PESQUISA!$C$50,$I17)),1,0)) | AC17: =IF($AB17=1,SUM($AB$3:$AB17),"")
J18: =IFERROR(INDEX(CONFIGURACOES!$G$37:$G$300,MATCH($I18,CONFIGURACOES!$B$37:$B$300,0)),"") | K18: =IFERROR(INDEX(CONFIGURACOES!$H$37:$H$300,MATCH($I18,CONFIGURACOES!$B$37:$B$300,0)),"") | M18: =IFERROR(INDEX(CONFIGURACOES!$I$37:$I$300,MATCH($I18,CONFIGURACOES!$B$37:$B$300,0)),"") | R18: =IF($N18="","",$N18*IF($Q18="",1,$Q18)*IF($P18="",1,$P18)*IF($O18="",1,$O18)) | S18: =IFERROR(INDEX(CONFIGURACOES!$J$37:$J$300,MATCH($I18,CONFIGURACOES!$B$37:$B$300,0)),"") | T18: =IF(OR($R18="",$S18=""),"",$R18*$S18) | X18: =IF($A18="","",$A18&"|"&$C18&"|"&$I18) | Y18: =IF(AND($A18=RELATORIO_MEDICAO!$C$5,$C18=RELATORIO_MEDICAO!$F$5,$A18<>""),COUNTIFS($A$3:$A18,RELATORIO_MEDICAO!$C$5,$C$3:$C18,RELATORIO_MEDICAO!$F$5),"") | Z18: =IF(OR($A18="",PESQUISA!$C$4=""),0,IF(OR(ISNUMBER(SEARCH(PESQUISA!$C$4,$G18)),ISNUMBER(SEARCH(PESQUISA!$C$4,$K18)),ISNUMBER(SEARCH(PESQUISA!$C$4,$L18))),1,0)) | AA18: =IF($Z18=1,SUM($Z$3:$Z18),"") | AB18: =IF(OR($A18="",PESQUISA!$C$50=""),0,IF(ISNUMBER(SEARCH(PESQUISA!$C$50,$I18)),1,0)) | AC18: =IF($AB18=1,SUM($AB$3:$AB18),"")
J19: =IFERROR(INDEX(CONFIGURACOES!$G$37:$G$300,MATCH($I19,CONFIGURACOES!$B$37:$B$300,0)),"") | K19: =IFERROR(INDEX(CONFIGURACOES!$H$37:$H$300,MATCH($I19,CONFIGURACOES!$B$37:$B$300,0)),"") | M19: =IFERROR(INDEX(CONFIGURACOES!$I$37:$I$300,MATCH($I19,CONFIGURACOES!$B$37:$B$300,0)),"") | R19: =IF($N19="","",$N19*IF($Q19="",1,$Q19)*IF($P19="",1,$P19)*IF($O19="",1,$O19)) | S19: =IFERROR(INDEX(CONFIGURACOES!$J$37:$J$300,MATCH($I19,CONFIGURACOES!$B$37:$B$300,0)),"") | T19: =IF(OR($R19="",$S19=""),"",$R19*$S19) | X19: =IF($A19="","",$A19&"|"&$C19&"|"&$I19) | Y19: =IF(AND($A19=RELATORIO_MEDICAO!$C$5,$C19=RELATORIO_MEDICAO!$F$5,$A19<>""),COUNTIFS($A$3:$A19,RELATORIO_MEDICAO!$C$5,$C$3:$C19,RELATORIO_MEDICAO!$F$5),"") | Z19: =IF(OR($A19="",PESQUISA!$C$4=""),0,IF(OR(ISNUMBER(SEARCH(PESQUISA!$C$4,$G19)),ISNUMBER(SEARCH(PESQUISA!$C$4,$K19)),ISNUMBER(SEARCH(PESQUISA!$C$4,$L19))),1,0)) | AA19: =IF($Z19=1,SUM($Z$3:$Z19),"") | AB19: =IF(OR($A19="",PESQUISA!$C$50=""),0,IF(ISNUMBER(SEARCH(PESQUISA!$C$50,$I19)),1,0)) | AC19: =IF($AB19=1,SUM($AB$3:$AB19),"")
J20: =IFERROR(INDEX(CONFIGURACOES!$G$37:$G$300,MATCH($I20,CONFIGURACOES!$B$37:$B$300,0)),"") | K20: =IFERROR(INDEX(CONFIGURACOES!$H$37:$H$300,MATCH($I20,CONFIGURACOES!$B$37:$B$300,0)),"") | M20: =IFERROR(INDEX(CONFIGURACOES!$I$37:$I$300,MATCH($I20,CONFIGURACOES!$B$37:$B$300,0)),"") | R20: =IF($N20="","",$N20*IF($Q20="",1,$Q20)*IF($P20="",1,$P20)*IF($O20="",1,$O20)) | S20: =IFERROR(INDEX(CONFIGURACOES!$J$37:$J$300,MATCH($I20,CONFIGURACOES!$B$37:$B$300,0)),"") | T20: =IF(OR($R20="",$S20=""),"",$R20*$S20) | X20: =IF($A20="","",$A20&"|"&$C20&"|"&$I20) | Y20: =IF(AND($A20=RELATORIO_MEDICAO!$C$5,$C20=RELATORIO_MEDICAO!$F$5,$A20<>""),COUNTIFS($A$3:$A20,RELATORIO_MEDICAO!$C$5,$C$3:$C20,RELATORIO_MEDICAO!$F$5),"") | Z20: =IF(OR($A20="",PESQUISA!$C$4=""),0,IF(OR(ISNUMBER(SEARCH(PESQUISA!$C$4,$G20)),ISNUMBER(SEARCH(PESQUISA!$C$4,$K20)),ISNUMBER(SEARCH(PESQUISA!$C$4,$L20))),1,0)) | AA20: =IF($Z20=1,SUM($Z$3:$Z20),"") | AB20: =IF(OR($A20="",PESQUISA!$C$50=""),0,IF(ISNUMBER(SEARCH(PESQUISA!$C$50,$I20)),1,0)) | AC20: =IF($AB20=1,SUM($AB$3:$AB20),"")
J21: =IFERROR(INDEX(CONFIGURACOES!$G$37:$G$300,MATCH($I21,CONFIGURACOES!$B$37:$B$300,0)),"") | K21: =IFERROR(INDEX(CONFIGURACOES!$H$37:$H$300,MATCH($I21,CONFIGURACOES!$B$37:$B$300,0)),"") | M21: =IFERROR(INDEX(CONFIGURACOES!$I$37:$I$300,MATCH($I21,CONFIGURACOES!$B$37:$B$300,0)),"") | R21: =IF($N21="","",$N21*IF($Q21="",1,$Q21)*IF($P21="",1,$P21)*IF($O21="",1,$O21)) | S21: =IFERROR(INDEX(CONFIGURACOES!$J$37:$J$300,MATCH($I21,CONFIGURACOES!$B$37:$B$300,0)),"") | T21: =IF(OR($R21="",$S21=""),"",$R21*$S21) | X21: =IF($A21="","",$A21&"|"&$C21&"|"&$I21) | Y21: =IF(AND($A21=RELATORIO_MEDICAO!$C$5,$C21=RELATORIO_MEDICAO!$F$5,$A21<>""),COUNTIFS($A$3:$A21,RELATORIO_MEDICAO!$C$5,$C$3:$C21,RELATORIO_MEDICAO!$F$5),"") | Z21: =IF(OR($A21="",PESQUISA!$C$4=""),0,IF(OR(ISNUMBER(SEARCH(PESQUISA!$C$4,$G21)),ISNUMBER(SEARCH(PESQUISA!$C$4,$K21)),ISNUMBER(SEARCH(PESQUISA!$C$4,$L21))),1,0)) | AA21: =IF($Z21=1,SUM($Z$3:$Z21),"") | AB21: =IF(OR($A21="",PESQUISA!$C$50=""),0,IF(ISNUMBER(SEARCH(PESQUISA!$C$50,$I21)),1,0)) | AC21: =IF($AB21=1,SUM($AB$3:$AB21),"")
J22: =IFERROR(INDEX(CONFIGURACOES!$G$37:$G$300,MATCH($I22,CONFIGURACOES!$B$37:$B$300,0)),"") | K22: =IFERROR(INDEX(CONFIGURACOES!$H$37:$H$300,MATCH($I22,CONFIGURACOES!$B$37:$B$300,0)),"") | M22: =IFERROR(INDEX(CONFIGURACOES!$I$37:$I$300,MATCH($I22,CONFIGURACOES!$B$37:$B$300,0)),"") | R22: =IF($N22="","",$N22*IF($Q22="",1,$Q22)*IF($P22="",1,$P22)*IF($O22="",1,$O22)) | S22: =IFERROR(INDEX(CONFIGURACOES!$J$37:$J$300,MATCH($I22,CONFIGURACOES!$B$37:$B$300,0)),"") | T22: =IF(OR($R22="",$S22=""),"",$R22*$S22) | X22: =IF($A22="","",$A22&"|"&$C22&"|"&$I22) | Y22: =IF(AND($A22=RELATORIO_MEDICAO!$C$5,$C22=RELATORIO_MEDICAO!$F$5,$A22<>""),COUNTIFS($A$3:$A22,RELATORIO_MEDICAO!$C$5,$C$3:$C22,RELATORIO_MEDICAO!$F$5),"") | Z22: =IF(OR($A22="",PESQUISA!$C$4=""),0,IF(OR(ISNUMBER(SEARCH(PESQUISA!$C$4,$G22)),ISNUMBER(SEARCH(PESQUISA!$C$4,$K22)),ISNUMBER(SEARCH(PESQUISA!$C$4,$L22))),1,0)) | AA22: =IF($Z22=1,SUM($Z$3:$Z22),"") | AB22: =IF(OR($A22="",PESQUISA!$C$50=""),0,IF(ISNUMBER(SEARCH(PESQUISA!$C$50,$I22)),1,0)) | AC22: =IF($AB22=1,SUM($AB$3:$AB22),"")
... J2002: =IFERROR(INDEX(CONFIGURACOES!$G$37:$G$300,MATCH($I2002,CONFIGURACOES!$B$37:$B$300,0)),"") | K2002: =IFERROR(INDEX(CONFIGURACOES!$H$37:$H$300,MATCH($I2002,CONFIGURACOES!$B$37:$B$300,0)),"") | M2002: =IFERROR(INDEX(CONFIGURACOES!$I$37:$I$300,MATCH($I2002,CONFIGURACOES!$B$37:$B$300,0)),"") | R2002: =IF($N2002="","",$N2002*IF($Q2002="",1,$Q2002)*IF($P2002="",1,$P2002)*IF($O2002="",1,$O2002)) | S2002: =IFERROR(INDEX(CONFIGURACOES!$J$37:$J$300,MATCH($I2002,CONFIGURACOES!$B$37:$B$300,0)),"") | T2002: =IF(OR($R2002="",$S2002=""),"",$R2002*$S2002) | X2002: =IF($A2002="","",$A2002&"|"&$C2002&"|"&$I2002) | Y2002: =IF(AND($A2002=RELATORIO_MEDICAO!$C$5,$C2002=RELATORIO_MEDICAO!$F$5,$A2002<>""),COUNTIFS($A$3:$A2002,RELATORIO_MEDICAO!$C$5,$C$3:$C2002,RELATORIO_MEDICAO!$F$5),"") | Z2002: =IF(OR($A2002="",PESQUISA!$C$4=""),0,IF(OR(ISNUMBER(SEARCH(PESQUISA!$C$4,$G2002)),ISNUMBER(SEARCH(PESQUISA!$C$4,$K2002)),ISNUMBER(SEARCH(PESQUISA!$C$4,$L2002))),1,0)) | AA2002: =IF($Z2002=1,SUM($Z$3:$Z2002),"") | AB2002: =IF(OR($A2002="",PESQUISA!$C$50=""),0,IF(ISNUMBER(SEARCH(PESQUISA!$C$50,$I2002)),1,0)) | AC2002: =IF($AB2002=1,SUM($AB$3:$AB2002),"")

Sheet PESQUISA
A1: PESQUISA / CONSULTA DE MEDICOES
A2: Pesquisa funcional (formulas), sem necessidade de macros. Aceita parte do texto.
B3: PESQUISAR POR CT OU TEXTO BREVE (aceita parte do texto, ex.: 'PINTURA' ou 'RESTAURANTE')
B4: Digite aqui:
B6: NOTA | C6: MEDICAO | D6: ITEM | E6: CT | F6: ATIVIDADE | G6: DESCRICAO | H6: UND. | I6: VALOR TOTAL
B7: =IFERROR(INDEX(HISTORICO!$A$3:$A$2002,MATCH(1,HISTORICO!$AA$3:$AA$2002,0)),"") | C7: =IFERROR(INDEX(HISTORICO!$C$3:$C$2002,MATCH(1,HISTORICO!$AA$3:$AA$2002,0)),"") | D7: =IFERROR(INDEX(HISTORICO!$I$3:$I$2002,MATCH(1,HISTORICO!$AA$3:$AA$2002,0)),"") | E7: =IFERROR(INDEX(HISTORICO!$G$3:$G$2002,MATCH(1,HISTORICO!$AA$3:$AA$2002,0)),"") | F7: =IFERROR(INDEX(HISTORICO!$K$3:$K$2002,MATCH(1,HISTORICO!$AA$3:$AA$2002,0)),"") | G7: =IFERROR(INDEX(HISTORICO!$L$3:$L$2002,MATCH(1,HISTORICO!$AA$3:$AA$2002,0)),"") | H7: =IFERROR(INDEX(HISTORICO!$M$3:$M$2002,MATCH(1,HISTORICO!$AA$3:$AA$2002,0)),"") | I7: =IFERROR(INDEX(HISTORICO!$T$3:$T$2002,MATCH(1,HISTORICO!$AA$3:$AA$2002,0)),"")
B8: =IFERROR(INDEX(HISTORICO!$A$3:$A$2002,MATCH(2,HISTORICO!$AA$3:$AA$2002,0)),"") | C8: =IFERROR(INDEX(HISTORICO!$C$3:$C$2002,MATCH(2,HISTORICO!$AA$3:$AA$2002,0)),"") | D8: =IFERROR(INDEX(HISTORICO!$I$3:$I$2002,MATCH(2,HISTORICO!$AA$3:$AA$2002,0)),"") | E8: =IFERROR(INDEX(HISTORICO!$G$3:$G$2002,MATCH(2,HISTORICO!$AA$3:$AA$2002,0)),"") | F8: =IFERROR(INDEX(HISTORICO!$K$3:$K$2002,MATCH(2,HISTORICO!$AA$3:$AA$2002,0)),"") | G8: =IFERROR(INDEX(HISTORICO!$L$3:$L$2002,MATCH(2,HISTORICO!$AA$3:$AA$2002,0)),"") | H8: =IFERROR(INDEX(HISTORICO!$M$3:$M$2002,MATCH(2,HISTORICO!$AA$3:$AA$2002,0)),"") | I8: =IFERROR(INDEX(HISTORICO!$T$3:$T$2002,MATCH(2,HISTORICO!$AA$3:$AA$2002,0)),"")
B9: =IFERROR(INDEX(HISTORICO!$A$3:$A$2002,MATCH(3,HISTORICO!$AA$3:$AA$2002,0)),"") | C9: =IFERROR(INDEX(HISTORICO!$C$3:$C$2002,MATCH(3,HISTORICO!$AA$3:$AA$2002,0)),"") | D9: =IFERROR(INDEX(HISTORICO!$I$3:$I$2002,MATCH(3,HISTORICO!$AA$3:$AA$2002,0)),"") | E9: =IFERROR(INDEX(HISTORICO!$G$3:$G$2002,MATCH(3,HISTORICO!$AA$3:$AA$2002,0)),"") | F9: =IFERROR(INDEX(HISTORICO!$K$3:$K$2002,MATCH(3,HISTORICO!$AA$3:$AA$2002,0)),"") | G9: =IFERROR(INDEX(HISTORICO!$L$3:$L$2002,MATCH(3,HISTORICO!$AA$3:$AA$2002,0)),"") | H9: =IFERROR(INDEX(HISTORICO!$M$3:$M$2002,MATCH(3,HISTORICO!$AA$3:$AA$2002,0)),"") | I9: =IFERROR(INDEX(HISTORICO!$T$3:$T$2002,MATCH(3,HISTORICO!$AA$3:$AA$2002,0)),"")
B10: =IFERROR(INDEX(HISTORICO!$A$3:$A$2002,MATCH(4,HISTORICO!$AA$3:$AA$2002,0)),"") | C10: =IFERROR(INDEX(HISTORICO!$C$3:$C$2002,MATCH(4,HISTORICO!$AA$3:$AA$2002,0)),"") | D10: =IFERROR(INDEX(HISTORICO!$I$3:$I$2002,MATCH(4,HISTORICO!$AA$3:$AA$2002,0)),"") | E10: =IFERROR(INDEX(HISTORICO!$G$3:$G$2002,MATCH(4,HISTORICO!$AA$3:$AA$2002,0)),"") | F10: =IFERROR(INDEX(HISTORICO!$K$3:$K$2002,MATCH(4,HISTORICO!$AA$3:$AA$2002,0)),"") | G10: =IFERROR(INDEX(HISTORICO!$L$3:$L$2002,MATCH(4,HISTORICO!$AA$3:$AA$2002,0)),"") | H10: =IFERROR(INDEX(HISTORICO!$M$3:$M$2002,MATCH(4,HISTORICO!$AA$3:$AA$2002,0)),"") | I10: =IFERROR(INDEX(HISTORICO!$T$3:$T$2002,MATCH(4,HISTORICO!$AA$3:$AA$2002,0)),"")
B11: =IFERROR(INDEX(HISTORICO!$A$3:$A$2002,MATCH(5,HISTORICO!$AA$3:$AA$2002,0)),"") | C11: =IFERROR(INDEX(HISTORICO!$C$3:$C$2002,MATCH(5,HISTORICO!$AA$3:$AA$2002,0)),"") | D11: =IFERROR(INDEX(HISTORICO!$I$3:$I$2002,MATCH(5,HISTORICO!$AA$3:$AA$2002,0)),"") | E11: =IFERROR(INDEX(HISTORICO!$G$3:$G$2002,MATCH(5,HISTORICO!$AA$3:$AA$2002,0)),"") | F11: =IFERROR(INDEX(HISTORICO!$K$3:$K$2002,MATCH(5,HISTORICO!$AA$3:$AA$2002,0)),"") | G11: =IFERROR(INDEX(HISTORICO!$L$3:$L$2002,MATCH(5,HISTORICO!$AA$3:$AA$2002,0)),"") | H11: =IFERROR(INDEX(HISTORICO!$M$3:$M$2002,MATCH(5,HISTORICO!$AA$3:$AA$2002,0)),"") | I11: =IFERROR(INDEX(HISTORICO!$T$3:$T$2002,MATCH(5,HISTORICO!$AA$3:$AA$2002,0)),"")
B12: =IFERROR(INDEX(HISTORICO!$A$3:$A$2002,MATCH(6,HISTORICO!$AA$3:$AA$2002,0)),"") | C12: =IFERROR(INDEX(HISTORICO!$C$3:$C$2002,MATCH(6,HISTORICO!$AA$3:$AA$2002,0)),"") | D12: =IFERROR(INDEX(HISTORICO!$I$3:$I$2002,MATCH(6,HISTORICO!$AA$3:$AA$2002,0)),"") | E12: =IFERROR(INDEX(HISTORICO!$G$3:$G$2002,MATCH(6,HISTORICO!$AA$3:$AA$2002,0)),"") | F12: =IFERROR(INDEX(HISTORICO!$K$3:$K$2002,MATCH(6,HISTORICO!$AA$3:$AA$2002,0)),"") | G12: =IFERROR(INDEX(HISTORICO!$L$3:$L$2002,MATCH(6,HISTORICO!$AA$3:$AA$2002,0)),"") | H12: =IFERROR(INDEX(HISTORICO!$M$3:$M$2002,MATCH(6,HISTORICO!$AA$3:$AA$2002,0)),"") | I12: =IFERROR(INDEX(HISTORICO!$T$3:$T$2002,MATCH(6,HISTORICO!$AA$3:$AA$2002,0)),"")
B13: =IFERROR(INDEX(HISTORICO!$A$3:$A$2002,MATCH(7,HISTORICO!$AA$3:$AA$2002,0)),"") | C13: =IFERROR(INDEX(HISTORICO!$C$3:$C$2002,MATCH(7,HISTORICO!$AA$3:$AA$2002,0)),"") | D13: =IFERROR(INDEX(HISTORICO!$I$3:$I$2002,MATCH(7,HISTORICO!$AA$3:$AA$2002,0)),"") | E13: =IFERROR(INDEX(HISTORICO!$G$3:$G$2002,MATCH(7,HISTORICO!$AA$3:$AA$2002,0)),"") | F13: =IFERROR(INDEX(HISTORICO!$K$3:$K$2002,MATCH(7,HISTORICO!$AA$3:$AA$2002,0)),"") | G13: =IFERROR(INDEX(HISTORICO!$L$3:$L$2002,MATCH(7,HISTORICO!$AA$3:$AA$2002,0)),"") | H13: =IFERROR(INDEX(HISTORICO!$M$3:$M$2002,MATCH(7,HISTORICO!$AA$3:$AA$2002,0)),"") | I13: =IFERROR(INDEX(HISTORICO!$T$3:$T$2002,MATCH(7,HISTORICO!$AA$3:$AA$2002,0)),"")
B14: =IFERROR(INDEX(HISTORICO!$A$3:$A$2002,MATCH(8,HISTORICO!$AA$3:$AA$2002,0)),"") | C14: =IFERROR(INDEX(HISTORICO!$C$3:$C$2002,MATCH(8,HISTORICO!$AA$3:$AA$2002,0)),"") | D14: =IFERROR(INDEX(HISTORICO!$I$3:$I$2002,MATCH(8,HISTORICO!$AA$3:$AA$2002,0)),"") | E14: =IFERROR(INDEX(HISTORICO!$G$3:$G$2002,MATCH(8,HISTORICO!$AA$3:$AA$2002,0)),"") | F14: =IFERROR(INDEX(HISTORICO!$K$3:$K$2002,MATCH(8,HISTORICO!$AA$3:$AA$2002,0)),"") | G14: =IFERROR(INDEX(HISTORICO!$L$3:$L$2002,MATCH(8,HISTORICO!$AA$3:$AA$2002,0)),"") | H14: =IFERROR(INDEX(HISTORICO!$M$3:$M$2002,MATCH(8,HISTORICO!$AA$3:$AA$2002,0)),"") | I14: =IFERROR(INDEX(HISTORICO!$T$3:$T$2002,MATCH(8,HISTORICO!$AA$3:$AA$2002,0)),"")
B15: =IFERROR(INDEX(HISTORICO!$A$3:$A$2002,MATCH(9,HISTORICO!$AA$3:$AA$2002,0)),"") | C15: =IFERROR(INDEX(HISTORICO!$C$3:$C$2002,MATCH(9,HISTORICO!$AA$3:$AA$2002,0)),"") | D15: =IFERROR(INDEX(HISTORICO!$I$3:$I$2002,MATCH(9,HISTORICO!$AA$3:$AA$2002,0)),"") | E15: =IFERROR(INDEX(HISTORICO!$G$3:$G$2002,MATCH(9,HISTORICO!$AA$3:$AA$2002,0)),"") | F15: =IFERROR(INDEX(HISTORICO!$K$3:$K$2002,MATCH(9,HISTORICO!$AA$3:$AA$2002,0)),"") | G15: =IFERROR(INDEX(HISTORICO!$L$3:$L$2002,MATCH(9,HISTORICO!$AA$3:$AA$2002,0)),"") | H15: =IFERROR(INDEX(HISTORICO!$M$3:$M$2002,MATCH(9,HISTORICO!$AA$3:$AA$2002,0)),"") | I15: =IFERROR(INDEX(HISTORICO!$T$3:$T$2002,MATCH(9,HISTORICO!$AA$3:$AA$2002,0)),"")
B16: =IFERROR(INDEX(HISTORICO!$A$3:$A$2002,MATCH(10,HISTORICO!$AA$3:$AA$2002,0)),"") | C16: =IFERROR(INDEX(HISTORICO!$C$3:$C$2002,MATCH(10,HISTORICO!$AA$3:$AA$2002,0)),"") | D16: =IFERROR(INDEX(HISTORICO!$I$3:$I$2002,MATCH(10,HISTORICO!$AA$3:$AA$2002,0)),"") | E16: =IFERROR(INDEX(HISTORICO!$G$3:$G$2002,MATCH(10,HISTORICO!$AA$3:$AA$2002,0)),"") | F16: =IFERROR(INDEX(HISTORICO!$K$3:$K$2002,MATCH(10,HISTORICO!$AA$3:$AA$2002,0)),"") | G16: =IFERROR(INDEX(HISTORICO!$L$3:$L$2002,MATCH(10,HISTORICO!$AA$3:$AA$2002,0)),"") | H16: =IFERROR(INDEX(HISTORICO!$M$3:$M$2002,MATCH(10,HISTORICO!$AA$3:$AA$2002,0)),"") | I16: =IFERROR(INDEX(HISTORICO!$T$3:$T$2002,MATCH(10,HISTORICO!$AA$3:$AA$2002,0)),"")
B17: =IFERROR(INDEX(HISTORICO!$A$3:$A$2002,MATCH(11,HISTORICO!$AA$3:$AA$2002,0)),"") | C17: =IFERROR(INDEX(HISTORICO!$C$3:$C$2002,MATCH(11,HISTORICO!$AA$3:$AA$2002,0)),"") | D17: =IFERROR(INDEX(HISTORICO!$I$3:$I$2002,MATCH(11,HISTORICO!$AA$3:$AA$2002,0)),"") | E17: =IFERROR(INDEX(HISTORICO!$G$3:$G$2002,MATCH(11,HISTORICO!$AA$3:$AA$2002,0)),"") | F17: =IFERROR(INDEX(HISTORICO!$K$3:$K$2002,MATCH(11,HISTORICO!$AA$3:$AA$2002,0)),"") | G17: =IFERROR(INDEX(HISTORICO!$L$3:$L$2002,MATCH(11,HISTORICO!$AA$3:$AA$2002,0)),"") | H17: =IFERROR(INDEX(HISTORICO!$M$3:$M$2002,MATCH(11,HISTORICO!$AA$3:$AA$2002,0)),"") | I17: =IFERROR(INDEX(HISTORICO!$T$3:$T$2002,MATCH(11,HISTORICO!$AA$3:$AA$2002,0)),"")
B18: =IFERROR(INDEX(HISTORICO!$A$3:$A$2002,MATCH(12,HISTORICO!$AA$3:$AA$2002,0)),"") | C18: =IFERROR(INDEX(HISTORICO!$C$3:$C$2002,MATCH(12,HISTORICO!$AA$3:$AA$2002,0)),"") | D18: =IFERROR(INDEX(HISTORICO!$I$3:$I$2002,MATCH(12,HISTORICO!$AA$3:$AA$2002,0)),"") | E18: =IFERROR(INDEX(HISTORICO!$G$3:$G$2002,MATCH(12,HISTORICO!$AA$3:$AA$2002,0)),"") | F18: =IFERROR(INDEX(HISTORICO!$K$3:$K$2002,MATCH(12,HISTORICO!$AA$3:$AA$2002,0)),"") | G18: =IFERROR(INDEX(HISTORICO!$L$3:$L$2002,MATCH(12,HISTORICO!$AA$3:$AA$2002,0)),"") | H18: =IFERROR(INDEX(HISTORICO!$M$3:$M$2002,MATCH(12,HISTORICO!$AA$3:$AA$2002,0)),"") | I18: =IFERROR(INDEX(HISTORICO!$T$3:$T$2002,MATCH(12,HISTORICO!$AA$3:$AA$2002,0)),"")
B19: =IFERROR(INDEX(HISTORICO!$A$3:$A$2002,MATCH(13,HISTORICO!$AA$3:$AA$2002,0)),"") | C19: =IFERROR(INDEX(HISTORICO!$C$3:$C$2002,MATCH(13,HISTORICO!$AA$3:$AA$2002,0)),"") | D19: =IFERROR(INDEX(HISTORICO!$I$3:$I$2002,MATCH(13,HISTORICO!$AA$3:$AA$2002,0)),"") | E19: =IFERROR(INDEX(HISTORICO!$G$3:$G$2002,MATCH(13,HISTORICO!$AA$3:$AA$2002,0)),"") | F19: =IFERROR(INDEX(HISTORICO!$K$3:$K$2002,MATCH(13,HISTORICO!$AA$3:$AA$2002,0)),"") | G19: =IFERROR(INDEX(HISTORICO!$L$3:$L$2002,MATCH(13,HISTORICO!$AA$3:$AA$2002,0)),"") | H19: =IFERROR(INDEX(HISTORICO!$M$3:$M$2002,MATCH(13,HISTORICO!$AA$3:$AA$2002,0)),"") | I19: =IFERROR(INDEX(HISTORICO!$T$3:$T$2002,MATCH(13,HISTORICO!$AA$3:$AA$2002,0)),"")
B20: =IFERROR(INDEX(HISTORICO!$A$3:$A$2002,MATCH(14,HISTORICO!$AA$3:$AA$2002,0)),"") | C20: =IFERROR(INDEX(HISTORICO!$C$3:$C$2002,MATCH(14,HISTORICO!$AA$3:$AA$2002,0)),"") | D20: =IFERROR(INDEX(HISTORICO!$I$3:$I$2002,MATCH(14,HISTORICO!$AA$3:$AA$2002,0)),"") | E20: =IFERROR(INDEX(HISTORICO!$G$3:$G$2002,MATCH(14,HISTORICO!$AA$3:$AA$2002,0)),"") | F20: =IFERROR(INDEX(HISTORICO!$K$3:$K$2002,MATCH(14,HISTORICO!$AA$3:$AA$2002,0)),"") | G20: =IFERROR(INDEX(HISTORICO!$L$3:$L$2002,MATCH(14,HISTORICO!$AA$3:$AA$2002,0)),"") | H20: =IFERROR(INDEX(HISTORICO!$M$3:$M$2002,MATCH(14,HISTORICO!$AA$3:$AA$2002,0)),"") | I20: =IFERROR(INDEX(HISTORICO!$T$3:$T$2002,MATCH(14,HISTORICO!$AA$3:$AA$2002,0)),"")
B21: =IFERROR(INDEX(HISTORICO!$A$3:$A$2002,MATCH(15,HISTORICO!$AA$3:$AA$2002,0)),"") | C21: =IFERROR(INDEX(HISTORICO!$C$3:$C$2002,MATCH(15,HISTORICO!$AA$3:$AA$2002,0)),"") | D21: =IFERROR(INDEX(HISTORICO!$I$3:$I$2002,MATCH(15,HISTORICO!$AA$3:$AA$2002,0)),"") | E21: =IFERROR(INDEX(HISTORICO!$G$3:$G$2002,MATCH(15,HISTORICO!$AA$3:$AA$2002,0)),"") | F21: =IFERROR(INDEX(HISTORICO!$K$3:$K$2002,MATCH(15,HISTORICO!$AA$3:$AA$2002,0)),"") | G21: =IFERROR(INDEX(HISTORICO!$L$3:$L$2002,MATCH(15,HISTORICO!$AA$3:$AA$2002,0)),"") | H21: =IFERROR(INDEX(HISTORICO!$M$3:$M$2002,MATCH(15,HISTORICO!$AA$3:$AA$2002,0)),"") | I21: =IFERROR(INDEX(HISTORICO!$T$3:$T$2002,MATCH(15,HISTORICO!$AA$3:$AA$2002,0)),"")
B22: =IFERROR(INDEX(HISTORICO!$A$3:$A$2002,MATCH(16,HISTORICO!$AA$3:$AA$2002,0)),"") | C22: =IFERROR(INDEX(HISTORICO!$C$3:$C$2002,MATCH(16,HISTORICO!$AA$3:$AA$2002,0)),"") | D22: =IFERROR(INDEX(HISTORICO!$I$3:$I$2002,MATCH(16,HISTORICO!$AA$3:$AA$2002,0)),"") | E22: =IFERROR(INDEX(HISTORICO!$G$3:$G$2002,MATCH(16,HISTORICO!$AA$3:$AA$2002,0)),"") | F22: =IFERROR(INDEX(HISTORICO!$K$3:$K$2002,MATCH(16,HISTORICO!$AA$3:$AA$2002,0)),"") | G22: =IFERROR(INDEX(HISTORICO!$L$3:$L$2002,MATCH(16,HISTORICO!$AA$3:$AA$2002,0)),"") | H22: =IFERROR(INDEX(HISTORICO!$M$3:$M$2002,MATCH(16,HISTORICO!$AA$3:$AA$2002,0)),"") | I22: =IFERROR(INDEX(HISTORICO!$T$3:$T$2002,MATCH(16,HISTORICO!$AA$3:$AA$2002,0)),"")
B23: =IFERROR(INDEX(HISTORICO!$A$3:$A$2002,MATCH(17,HISTORICO!$AA$3:$AA$2002,0)),"") | C23: =IFERROR(INDEX(HISTORICO!$C$3:$C$2002,MATCH(17,HISTORICO!$AA$3:$AA$2002,0)),"") | D23: =IFERROR(INDEX(HISTORICO!$I$3:$I$2002,MATCH(17,HISTORICO!$AA$3:$AA$2002,0)),"") | E23: =IFERROR(INDEX(HISTORICO!$G$3:$G$2002,MATCH(17,HISTORICO!$AA$3:$AA$2002,0)),"") | F23: =IFERROR(INDEX(HISTORICO!$K$3:$K$2002,MATCH(17,HISTORICO!$AA$3:$AA$2002,0)),"") | G23: =IFERROR(INDEX(HISTORICO!$L$3:$L$2002,MATCH(17,HISTORICO!$AA$3:$AA$2002,0)),"") | H23: =IFERROR(INDEX(HISTORICO!$M$3:$M$2002,MATCH(17,HISTORICO!$AA$3:$AA$2002,0)),"") | I23: =IFERROR(INDEX(HISTORICO!$T$3:$T$2002,MATCH(17,HISTORICO!$AA$3:$AA$2002,0)),"")
B24: =IFERROR(INDEX(HISTORICO!$A$3:$A$2002,MATCH(18,HISTORICO!$AA$3:$AA$2002,0)),"") | C24: =IFERROR(INDEX(HISTORICO!$C$3:$C$2002,MATCH(18,HISTORICO!$AA$3:$AA$2002,0)),"") | D24: =IFERROR(INDEX(HISTORICO!$I$3:$I$2002,MATCH(18,HISTORICO!$AA$3:$AA$2002,0)),"") | E24: =IFERROR(INDEX(HISTORICO!$G$3:$G$2002,MATCH(18,HISTORICO!$AA$3:$AA$2002,0)),"") | F24: =IFERROR(INDEX(HISTORICO!$K$3:$K$2002,MATCH(18,HISTORICO!$AA$3:$AA$2002,0)),"") | G24: =IFERROR(INDEX(HISTORICO!$L$3:$L$2002,MATCH(18,HISTORICO!$AA$3:$AA$2002,0)),"") | H24: =IFERROR(INDEX(HISTORICO!$M$3:$M$2002,MATCH(18,HISTORICO!$AA$3:$AA$2002,0)),"") | I24: =IFERROR(INDEX(HISTORICO!$T$3:$T$2002,MATCH(18,HISTORICO!$AA$3:$AA$2002,0)),"")
B25: =IFERROR(INDEX(HISTORICO!$A$3:$A$2002,MATCH(19,HISTORICO!$AA$3:$AA$2002,0)),"") | C25: =IFERROR(INDEX(HISTORICO!$C$3:$C$2002,MATCH(19,HISTORICO!$AA$3:$AA$2002,0)),"") | D25: =IFERROR(INDEX(HISTORICO!$I$3:$I$2002,MATCH(19,HISTORICO!$AA$3:$AA$2002,0)),"") | E25: =IFERROR(INDEX(HISTORICO!$G$3:$G$2002,MATCH(19,HISTORICO!$AA$3:$AA$2002,0)),"") | F25: =IFERROR(INDEX(HISTORICO!$K$3:$K$2002,MATCH(19,HISTORICO!$AA$3:$AA$2002,0)),"") | G25: =IFERROR(INDEX(HISTORICO!$L$3:$L$2002,MATCH(19,HISTORICO!$AA$3:$AA$2002,0)),"") | H25: =IFERROR(INDEX(HISTORICO!$M$3:$M$2002,MATCH(19,HISTORICO!$AA$3:$AA$2002,0)),"") | I25: =IFERROR(INDEX(HISTORICO!$T$3:$T$2002,MATCH(19,HISTORICO!$AA$3:$AA$2002,0)),"")
B26: =IFERROR(INDEX(HISTORICO!$A$3:$A$2002,MATCH(20,HISTORICO!$AA$3:$AA$2002,0)),"") | C26: =IFERROR(INDEX(HISTORICO!$C$3:$C$2002,MATCH(20,HISTORICO!$AA$3:$AA$2002,0)),"") | D26: =IFERROR(INDEX(HISTORICO!$I$3:$I$2002,MATCH(20,HISTORICO!$AA$3:$AA$2002,0)),"") | E26: =IFERROR(INDEX(HISTORICO!$G$3:$G$2002,MATCH(20,HISTORICO!$AA$3:$AA$2002,0)),"") | F26: =IFERROR(INDEX(HISTORICO!$K$3:$K$2002,MATCH(20,HISTORICO!$AA$3:$AA$2002,0)),"") | G26: =IFERROR(INDEX(HISTORICO!$L$3:$L$2002,MATCH(20,HISTORICO!$AA$3:$AA$2002,0)),"") | H26: =IFERROR(INDEX(HISTORICO!$M$3:$M$2002,MATCH(20,HISTORICO!$AA$3:$AA$2002,0)),"") | I26: =IFERROR(INDEX(HISTORICO!$T$3:$T$2002,MATCH(20,HISTORICO!$AA$3:$AA$2002,0)),"")
B27: =IFERROR(INDEX(HISTORICO!$A$3:$A$2002,MATCH(21,HISTORICO!$AA$3:$AA$2002,0)),"") | C27: =IFERROR(INDEX(HISTORICO!$C$3:$C$2002,MATCH(21,HISTORICO!$AA$3:$AA$2002,0)),"") | D27: =IFERROR(INDEX(HISTORICO!$I$3:$I$2002,MATCH(21,HISTORICO!$AA$3:$AA$2002,0)),"") | E27: =IFERROR(INDEX(HISTORICO!$G$3:$G$2002,MATCH(21,HISTORICO!$AA$3:$AA$2002,0)),"") | F27: =IFERROR(INDEX(HISTORICO!$K$3:$K$2002,MATCH(21,HISTORICO!$AA$3:$AA$2002,0)),"") | G27: =IFERROR(INDEX(HISTORICO!$L$3:$L$2002,MATCH(21,HISTORICO!$AA$3:$AA$2002,0)),"") | H27: =IFERROR(INDEX(HISTORICO!$M$3:$M$2002,MATCH(21,HISTORICO!$AA$3:$AA$2002,0)),"") | I27: =IFERROR(INDEX(HISTORICO!$T$3:$T$2002,MATCH(21,HISTORICO!$AA$3:$AA$2002,0)),"")
B28: =IFERROR(INDEX(HISTORICO!$A$3:$A$2002,MATCH(22,HISTORICO!$AA$3:$AA$2002,0)),"") | C28: =IFERROR(INDEX(HISTORICO!$C$3:$C$2002,MATCH(22,HISTORICO!$AA$3:$AA$2002,0)),"") | D28: =IFERROR(INDEX(HISTORICO!$I$3:$I$2002,MATCH(22,HISTORICO!$AA$3:$AA$2002,0)),"") | E28: =IFERROR(INDEX(HISTORICO!$G$3:$G$2002,MATCH(22,HISTORICO!$AA$3:$AA$2002,0)),"") | F28: =IFERROR(INDEX(HISTORICO!$K$3:$K$2002,MATCH(22,HISTORICO!$AA$3:$AA$2002,0)),"") | G28: =IFERROR(INDEX(HISTORICO!$L$3:$L$2002,MATCH(22,HISTORICO!$AA$3:$AA$2002,0)),"") | H28: =IFERROR(INDEX(HISTORICO!$M$3:$M$2002,MATCH(22,HISTORICO!$AA$3:$AA$2002,0)),"") | I28: =IFERROR(INDEX(HISTORICO!$T$3:$T$2002,MATCH(22,HISTORICO!$AA$3:$AA$2002,0)),"")
B29: =IFERROR(INDEX(HISTORICO!$A$3:$A$2002,MATCH(23,HISTORICO!$AA$3:$AA$2002,0)),"") | C29: =IFERROR(INDEX(HISTORICO!$C$3:$C$2002,MATCH(23,HISTORICO!$AA$3:$AA$2002,0)),"") | D29: =IFERROR(INDEX(HISTORICO!$I$3:$I$2002,MATCH(23,HISTORICO!$AA$3:$AA$2002,0)),"") | E29: =IFERROR(INDEX(HISTORICO!$G$3:$G$2002,MATCH(23,HISTORICO!$AA$3:$AA$2002,0)),"") | F29: =IFERROR(INDEX(HISTORICO!$K$3:$K$2002,MATCH(23,HISTORICO!$AA$3:$AA$2002,0)),"") | G29: =IFERROR(INDEX(HISTORICO!$L$3:$L$2002,MATCH(23,HISTORICO!$AA$3:$AA$2002,0)),"") | H29: =IFERROR(INDEX(HISTORICO!$M$3:$M$2002,MATCH(23,HISTORICO!$AA$3:$AA$2002,0)),"") | I29: =IFERROR(INDEX(HISTORICO!$T$3:$T$2002,MATCH(23,HISTORICO!$AA$3:$AA$2002,0)),"")
B30: =IFERROR(INDEX(HISTORICO!$A$3:$A$2002,MATCH(24,HISTORICO!$AA$3:$AA$2002,0)),"") | C30: =IFERROR(INDEX(HISTORICO!$C$3:$C$2002,MATCH(24,HISTORICO!$AA$3:$AA$2002,0)),"") | D30: =IFERROR(INDEX(HISTORICO!$I$3:$I$2002,MATCH(24,HISTORICO!$AA$3:$AA$2002,0)),"") | E30: =IFERROR(INDEX(HISTORICO!$G$3:$G$2002,MATCH(24,HISTORICO!$AA$3:$AA$2002,0)),"") | F30: =IFERROR(INDEX(HISTORICO!$K$3:$K$2002,MATCH(24,HISTORICO!$AA$3:$AA$2002,0)),"") | G30: =IFERROR(INDEX(HISTORICO!$L$3:$L$2002,MATCH(24,HISTORICO!$AA$3:$AA$2002,0)),"") | H30: =IFERROR(INDEX(HISTORICO!$M$3:$M$2002,MATCH(24,HISTORICO!$AA$3:$AA$2002,0)),"") | I30: =IFERROR(INDEX(HISTORICO!$T$3:$T$2002,MATCH(24,HISTORICO!$AA$3:$AA$2002,0)),"")
B31: =IFERROR(INDEX(HISTORICO!$A$3:$A$2002,MATCH(25,HISTORICO!$AA$3:$AA$2002,0)),"") | C31: =IFERROR(INDEX(HISTORICO!$C$3:$C$2002,MATCH(25,HISTORICO!$AA$3:$AA$2002,0)),"") | D31: =IFERROR(INDEX(HISTORICO!$I$3:$I$2002,MATCH(25,HISTORICO!$AA$3:$AA$2002,0)),"") | E31: =IFERROR(INDEX(HISTORICO!$G$3:$G$2002,MATCH(25,HISTORICO!$AA$3:$AA$2002,0)),"") | F31: =IFERROR(INDEX(HISTORICO!$K$3:$K$2002,MATCH(25,HISTORICO!$AA$3:$AA$2002,0)),"") | G31: =IFERROR(INDEX(HISTORICO!$L$3:$L$2002,MATCH(25,HISTORICO!$AA$3:$AA$2002,0)),"") | H31: =IFERROR(INDEX(HISTORICO!$M$3:$M$2002,MATCH(25,HISTORICO!$AA$3:$AA$2002,0)),"") | I31: =IFERROR(INDEX(HISTORICO!$T$3:$T$2002,MATCH(25,HISTORICO!$AA$3:$AA$2002,0)),"")
B32: =IFERROR(INDEX(HISTORICO!$A$3:$A$2002,MATCH(26,HISTORICO!$AA$3:$AA$2002,0)),"") | C32: =IFERROR(INDEX(HISTORICO!$C$3:$C$2002,MATCH(26,HISTORICO!$AA$3:$AA$2002,0)),"") | D32: =IFERROR(INDEX(HISTORICO!$I$3:$I$2002,MATCH(26,HISTORICO!$AA$3:$AA$2002,0)),"") | E32: =IFERROR(INDEX(HISTORICO!$G$3:$G$2002,MATCH(26,HISTORICO!$AA$3:$AA$2002,0)),"") | F32: =IFERROR(INDEX(HISTORICO!$K$3:$K$2002,MATCH(26,HISTORICO!$AA$3:$AA$2002,0)),"") | G32: =IFERROR(INDEX(HISTORICO!$L$3:$L$2002,MATCH(26,HISTORICO!$AA$3:$AA$2002,0)),"") | H32: =IFERROR(INDEX(HISTORICO!$M$3:$M$2002,MATCH(26,HISTORICO!$AA$3:$AA$2002,0)),"") | I32: =IFERROR(INDEX(HISTORICO!$T$3:$T$2002,MATCH(26,HISTORICO!$AA$3:$AA$2002,0)),"")
B33: =IFERROR(INDEX(HISTORICO!$A$3:$A$2002,MATCH(27,HISTORICO!$AA$3:$AA$2002,0)),"") | C33: =IFERROR(INDEX(HISTORICO!$C$3:$C$2002,MATCH(27,HISTORICO!$AA$3:$AA$2002,0)),"") | D33: =IFERROR(INDEX(HISTORICO!$I$3:$I$2002,MATCH(27,HISTORICO!$AA$3:$AA$2002,0)),"") | E33: =IFERROR(INDEX(HISTORICO!$G$3:$G$2002,MATCH(27,HISTORICO!$AA$3:$AA$2002,0)),"") | F33: =IFERROR(INDEX(HISTORICO!$K$3:$K$2002,MATCH(27,HISTORICO!$AA$3:$AA$2002,0)),"") | G33: =IFERROR(INDEX(HISTORICO!$L$3:$L$2002,MATCH(27,HISTORICO!$AA$3:$AA$2002,0)),"") | H33: =IFERROR(INDEX(HISTORICO!$M$3:$M$2002,MATCH(27,HISTORICO!$AA$3:$AA$2002,0)),"") | I33: =IFERROR(INDEX(HISTORICO!$T$3:$T$2002,MATCH(27,HISTORICO!$AA$3:$AA$2002,0)),"")
B34: =IFERROR(INDEX(HISTORICO!$A$3:$A$2002,MATCH(28,HISTORICO!$AA$3:$AA$2002,0)),"") | C34: =IFERROR(INDEX(HISTORICO!$C$3:$C$2002,MATCH(28,HISTORICO!$AA$3:$AA$2002,0)),"") | D34: =IFERROR(INDEX(HISTORICO!$I$3:$I$2002,MATCH(28,HISTORICO!$AA$3:$AA$2002,0)),"") | E34: =IFERROR(INDEX(HISTORICO!$G$3:$G$2002,MATCH(28,HISTORICO!$AA$3:$AA$2002,0)),"") | F34: =IFERROR(INDEX(HISTORICO!$K$3:$K$2002,MATCH(28,HISTORICO!$AA$3:$AA$2002,0)),"") | G34: =IFERROR(INDEX(HISTORICO!$L$3:$L$2002,MATCH(28,HISTORICO!$AA$3:$AA$2002,0)),"") | H34: =IFERROR(INDEX(HISTORICO!$M$3:$M$2002,MATCH(28,HISTORICO!$AA$3:$AA$2002,0)),"") | I34: =IFERROR(INDEX(HISTORICO!$T$3:$T$2002,MATCH(28,HISTORICO!$AA$3:$AA$2002,0)),"")
B35: =IFERROR(INDEX(HISTORICO!$A$3:$A$2002,MATCH(29,HISTORICO!$AA$3:$AA$2002,0)),"") | C35: =IFERROR(INDEX(HISTORICO!$C$3:$C$2002,MATCH(29,HISTORICO!$AA$3:$AA$2002,0)),"") | D35: =IFERROR(INDEX(HISTORICO!$I$3:$I$2002,MATCH(29,HISTORICO!$AA$3:$AA$2002,0)),"") | E35: =IFERROR(INDEX(HISTORICO!$G$3:$G$2002,MATCH(29,HISTORICO!$AA$3:$AA$2002,0)),"") | F35: =IFERROR(INDEX(HISTORICO!$K$3:$K$2002,MATCH(29,HISTORICO!$AA$3:$AA$2002,0)),"") | G35: =IFERROR(INDEX(HISTORICO!$L$3:$L$2002,MATCH(29,HISTORICO!$AA$3:$AA$2002,0)),"") | H35: =IFERROR(INDEX(HISTORICO!$M$3:$M$2002,MATCH(29,HISTORICO!$AA$3:$AA$2002,0)),"") | I35: =IFERROR(INDEX(HISTORICO!$T$3:$T$2002,MATCH(29,HISTORICO!$AA$3:$AA$2002,0)),"")
B36: =IFERROR(INDEX(HISTORICO!$A$3:$A$2002,MATCH(30,HISTORICO!$AA$3:$AA$2002,0)),"") | C36: =IFERROR(INDEX(HISTORICO!$C$3:$C$2002,MATCH(30,HISTORICO!$AA$3:$AA$2002,0)),"") | D36: =IFERROR(INDEX(HISTORICO!$I$3:$I$2002,MATCH(30,HISTORICO!$AA$3:$AA$2002,0)),"") | E36: =IFERROR(INDEX(HISTORICO!$G$3:$G$2002,MATCH(30,HISTORICO!$AA$3:$AA$2002,0)),"") | F36: =IFERROR(INDEX(HISTORICO!$K$3:$K$2002,MATCH(30,HISTORICO!$AA$3:$AA$2002,0)),"") | G36: =IFERROR(INDEX(HISTORICO!$L$3:$L$2002,MATCH(30,HISTORICO!$AA$3:$AA$2002,0)),"") | H36: =IFERROR(INDEX(HISTORICO!$M$3:$M$2002,MATCH(30,HISTORICO!$AA$3:$AA$2002,0)),"") | I36: =IFERROR(INDEX(HISTORICO!$T$3:$T$2002,MATCH(30,HISTORICO!$AA$3:$AA$2002,0)),"")
B37: =IFERROR(INDEX(HISTORICO!$A$3:$A$2002,MATCH(31,HISTORICO!$AA$3:$AA$2002,0)),"") | C37: =IFERROR(INDEX(HISTORICO!$C$3:$C$2002,MATCH(31,HISTORICO!$AA$3:$AA$2002,0)),"") | D37: =IFERROR(INDEX(HISTORICO!$I$3:$I$2002,MATCH(31,HISTORICO!$AA$3:$AA$2002,0)),"") | E37: =IFERROR(INDEX(HISTORICO!$G$3:$G$2002,MATCH(31,HISTORICO!$AA$3:$AA$2002,0)),"") | F37: =IFERROR(INDEX(HISTORICO!$K$3:$K$2002,MATCH(31,HISTORICO!$AA$3:$AA$2002,0)),"") | G37: =IFERROR(INDEX(HISTORICO!$L$3:$L$2002,MATCH(31,HISTORICO!$AA$3:$AA$2002,0)),"") | H37: =IFERROR(INDEX(HISTORICO!$M$3:$M$2002,MATCH(31,HISTORICO!$AA$3:$AA$2002,0)),"") | I37: =IFERROR(INDEX(HISTORICO!$T$3:$T$2002,MATCH(31,HISTORICO!$AA$3:$AA$2002,0)),"")
B38: =IFERROR(INDEX(HISTORICO!$A$3:$A$2002,MATCH(32,HISTORICO!$AA$3:$AA$2002,0)),"") | C38: =IFERROR(INDEX(HISTORICO!$C$3:$C$2002,MATCH(32,HISTORICO!$AA$3:$AA$2002,0)),"") | D38: =IFERROR(INDEX(HISTORICO!$I$3:$I$2002,MATCH(32,HISTORICO!$AA$3:$AA$2002,0)),"") | E38: =IFERROR(INDEX(HISTORICO!$G$3:$G$2002,MATCH(32,HISTORICO!$AA$3:$AA$2002,0)),"") | F38: =IFERROR(INDEX(HISTORICO!$K$3:$K$2002,MATCH(32,HISTORICO!$AA$3:$AA$2002,0)),"") | G38: =IFERROR(INDEX(HISTORICO!$L$3:$L$2002,MATCH(32,HISTORICO!$AA$3:$AA$2002,0)),"") | H38: =IFERROR(INDEX(HISTORICO!$M$3:$M$2002,MATCH(32,HISTORICO!$AA$3:$AA$2002,0)),"") | I38: =IFERROR(INDEX(HISTORICO!$T$3:$T$2002,MATCH(32,HISTORICO!$AA$3:$AA$2002,0)),"")
B39: =IFERROR(INDEX(HISTORICO!$A$3:$A$2002,MATCH(33,HISTORICO!$AA$3:$AA$2002,0)),"") | C39: =IFERROR(INDEX(HISTORICO!$C$3:$C$2002,MATCH(33,HISTORICO!$AA$3:$AA$2002,0)),"") | D39: =IFERROR(INDEX(HISTORICO!$I$3:$I$2002,MATCH(33,HISTORICO!$AA$3:$AA$2002,0)),"") | E39: =IFERROR(INDEX(HISTORICO!$G$3:$G$2002,MATCH(33,HISTORICO!$AA$3:$AA$2002,0)),"") | F39: =IFERROR(INDEX(HISTORICO!$K$3:$K$2002,MATCH(33,HISTORICO!$AA$3:$AA$2002,0)),"") | G39: =IFERROR(INDEX(HISTORICO!$L$3:$L$2002,MATCH(33,HISTORICO!$AA$3:$AA$2002,0)),"") | H39: =IFERROR(INDEX(HISTORICO!$M$3:$M$2002,MATCH(33,HISTORICO!$AA$3:$AA$2002,0)),"") | I39: =IFERROR(INDEX(HISTORICO!$T$3:$T$2002,MATCH(33,HISTORICO!$AA$3:$AA$2002,0)),"")
B40: =IFERROR(INDEX(HISTORICO!$A$3:$A$2002,MATCH(34,HISTORICO!$AA$3:$AA$2002,0)),"") | C40: =IFERROR(INDEX(HISTORICO!$C$3:$C$2002,MATCH(34,HISTORICO!$AA$3:$AA$2002,0)),"") | D40: =IFERROR(INDEX(HISTORICO!$I$3:$I$2002,MATCH(34,HISTORICO!$AA$3:$AA$2002,0)),"") | E40: =IFERROR(INDEX(HISTORICO!$G$3:$G$2002,MATCH(34,HISTORICO!$AA$3:$AA$2002,0)),"") | F40: =IFERROR(INDEX(HISTORICO!$K$3:$K$2002,MATCH(34,HISTORICO!$AA$3:$AA$2002,0)),"") | G40: =IFERROR(INDEX(HISTORICO!$L$3:$L$2002,MATCH(34,HISTORICO!$AA$3:$AA$2002,0)),"") | H40: =IFERROR(INDEX(HISTORICO!$M$3:$M$2002,MATCH(34,HISTORICO!$AA$3:$AA$2002,0)),"") | I40: =IFERROR(INDEX(HISTORICO!$T$3:$T$2002,MATCH(34,HISTORICO!$AA$3:$AA$2002,0)),"")
B41: =IFERROR(INDEX(HISTORICO!$A$3:$A$2002,MATCH(35,HISTORICO!$AA$3:$AA$2002,0)),"") | C41: =IFERROR(INDEX(HISTORICO!$C$3:$C$2002,MATCH(35,HISTORICO!$AA$3:$AA$2002,0)),"") | D41: =IFERROR(INDEX(HISTORICO!$I$3:$I$2002,MATCH(35,HISTORICO!$AA$3:$AA$2002,0)),"") | E41: =IFERROR(INDEX(HISTORICO!$G$3:$G$2002,MATCH(35,HISTORICO!$AA$3:$AA$2002,0)),"") | F41: =IFERROR(INDEX(HISTORICO!$K$3:$K$2002,MATCH(35,HISTORICO!$AA$3:$AA$2002,0)),"") | G41: =IFERROR(INDEX(HISTORICO!$L$3:$L$2002,MATCH(35,HISTORICO!$AA$3:$AA$2002,0)),"") | H41: =IFERROR(INDEX(HISTORICO!$M$3:$M$2002,MATCH(35,HISTORICO!$AA$3:$AA$2002,0)),"") | I41: =IFERROR(INDEX(HISTORICO!$T$3:$T$2002,MATCH(35,HISTORICO!$AA$3:$AA$2002,0)),"")
...

Sheet RELATORIO_MEDICAO
A1: =CONFIGURACOES!$C$7 | G1: =MOTOR_RELATORIO!$G$2
A2: RELATORIO DE MEDICAO
A3: Documento para conferencia e assinatura do FISCAL
A4: 🖨 GERAR PDF | D4: Botao visual: importe os modulos VBA (pasta /medicoes/vba) e clique com o botao direito aqui -> Atribuir Macro -> ExportarPDF. Nome sugerido do arquivo: CADENGECOM_NOTA_[nota]_MEDICAO_[medicao].pdf
A5: NUMERO DA NOTA: | C5: 29655103 | D5: MEDICAO: | F5: 1 | G5: TOTAL GERAL: | J5: =SUMIFS(HISTORICO!$T$3:$T$2002,HISTORICO!$A$3:$A$2002,$C$5,HISTORICO!$C$3:$C$2002,$F$5)
A6: DADOS DA MEDICAO
A7: NOTA: | B7: =$C$5 | C7: T.MED: | D7: =MOTOR_RELATORIO!$J$2 | E7: FISCAL: | F7: =MOTOR_RELATORIO!$E$2 | H7: C.C.:
A8: ELAB.: | B8: =MOTOR_RELATORIO!$I$2 | C8: CT: | D8: =MOTOR_RELATORIO!$F$2 | E8: SUPER.: | F8: =MOTOR_RELATORIO!$H$2 | H8: DATA: | I8: =MOTOR_RELATORIO!$K$2
A9: OBRA: | B9: =MOTOR_RELATORIO!$G$2
A10: ITENS DA MEDICAO
A11: =IFERROR(INDEX(MOTOR_RELATORIO!$Y$2:$Y$151,MATCH(1*10+1,MOTOR_RELATORIO!$AE$2:$AE$151,0)),"") | B11: =IFERROR(INDEX(MOTOR_RELATORIO!$Z$2:$Z$151,MATCH(1*10+1,MOTOR_RELATORIO!$AE$2:$AE$151,0)),"")
A12: =IFERROR(INDEX(MOTOR_RELATORIO!$AA$2:$AA$151,MATCH(1*10+1,MOTOR_RELATORIO!$AE$2:$AE$151,0)),"") | B12: =IFERROR(INDEX(MOTOR_RELATORIO!$AB$2:$AB$151,MATCH(1*10+1,MOTOR_RELATORIO!$AE$2:$AE$151,0)),"")
A13: ITEM | B13: LINHA | C13: DESCRICAO | E13: ATIVIDADE | G13: UND. | H13: X | I13: Y | J13: Z | K13: RESULTADO
A14: =IFERROR(INDEX(MOTOR_RELATORIO!$L$2:$L$151,MATCH(1*10+1,MOTOR_RELATORIO!$AE$2:$AE$151,0)),"") | B14: =IFERROR(INDEX(MOTOR_RELATORIO!$M$2:$M$151,MATCH(1*10+1,MOTOR_RELATORIO!$AE$2:$AE$151,0)),"") | E14: =IFERROR(INDEX(MOTOR_RELATORIO!$N$2:$N$151,MATCH(1*10+1,MOTOR_RELATORIO!$AE$2:$AE$151,0)),"") | G14: =IFERROR(INDEX(MOTOR_RELATORIO!$P$2:$P$151,MATCH(1*10+1,MOTOR_RELATORIO!$AE$2:$AE$151,0)),"")
C15: =IFERROR(INDEX(MOTOR_RELATORIO!$O$2:$O$151,MATCH(1*10+1,MOTOR_RELATORIO!$AE$2:$AE$151,0)),"") | H15: =IFERROR(INDEX(MOTOR_RELATORIO!$R$2:$R$151,MATCH(1*10+1,MOTOR_RELATORIO!$AE$2:$AE$151,0)),"") | I15: =IFERROR(INDEX(MOTOR_RELATORIO!$S$2:$S$151,MATCH(1*10+1,MOTOR_RELATORIO!$AE$2:$AE$151,0)),"") | J15: =IFERROR(INDEX(MOTOR_RELATORIO!$T$2:$T$151,MATCH(1*10+1,MOTOR_RELATORIO!$AE$2:$AE$151,0)),"") | K15: =IFERROR(INDEX(MOTOR_RELATORIO!$U$2:$U$151,MATCH(1*10+1,MOTOR_RELATORIO!$AE$2:$AE$151,0)),"")
C16: =IFERROR(INDEX(MOTOR_RELATORIO!$O$2:$O$151,MATCH(1*10+2,MOTOR_RELATORIO!$AE$2:$AE$151,0)),"") | H16: =IFERROR(INDEX(MOTOR_RELATORIO!$R$2:$R$151,MATCH(1*10+2,MOTOR_RELATORIO!$AE$2:$AE$151,0)),"") | I16: =IFERROR(INDEX(MOTOR_RELATORIO!$S$2:$S$151,MATCH(1*10+2,MOTOR_RELATORIO!$AE$2:$AE$151,0)),"") | J16: =IFERROR(INDEX(MOTOR_RELATORIO!$T$2:$T$151,MATCH(1*10+2,MOTOR_RELATORIO!$AE$2:$AE$151,0)),"") | K16: =IFERROR(INDEX(MOTOR_RELATORIO!$U$2:$U$151,MATCH(1*10+2,MOTOR_RELATORIO!$AE$2:$AE$151,0)),"")
C17: =IFERROR(INDEX(MOTOR_RELATORIO!$O$2:$O$151,MATCH(1*10+3,MOTOR_RELATORIO!$AE$2:$AE$151,0)),"") | H17: =IFERROR(INDEX(MOTOR_RELATORIO!$R$2:$R$151,MATCH(1*10+3,MOTOR_RELATORIO!$AE$2:$AE$151,0)),"") | I17: =IFERROR(INDEX(MOTOR_RELATORIO!$S$2:$S$151,MATCH(1*10+3,MOTOR_RELATORIO!$AE$2:$AE$151,0)),"") | J17: =IFERROR(INDEX(MOTOR_RELATORIO!$T$2:$T$151,MATCH(1*10+3,MOTOR_RELATORIO!$AE$2:$AE$151,0)),"") | K17: =IFERROR(INDEX(MOTOR_RELATORIO!$U$2:$U$151,MATCH(1*10+3,MOTOR_RELATORIO!$AE$2:$AE$151,0)),"")
C18: =IFERROR(INDEX(MOTOR_RELATORIO!$O$2:$O$151,MATCH(1*10+4,MOTOR_RELATORIO!$AE$2:$AE$151,0)),"") | H18: =IFERROR(INDEX(MOTOR_RELATORIO!$R$2:$R$151,MATCH(1*10+4,MOTOR_RELATORIO!$AE$2:$AE$151,0)),"") | I18: =IFERROR(INDEX(MOTOR_RELATORIO!$S$2:$S$151,MATCH(1*10+4,MOTOR_RELATORIO!$AE$2:$AE$151,0)),"") | J18: =IFERROR(INDEX(MOTOR_RELATORIO!$T$2:$T$151,MATCH(1*10+4,MOTOR_RELATORIO!$AE$2:$AE$151,0)),"") | K18: =IFERROR(INDEX(MOTOR_RELATORIO!$U$2:$U$151,MATCH(1*10+4,MOTOR_RELATORIO!$AE$2:$AE$151,0)),"")
C19: =IFERROR(INDEX(MOTOR_RELATORIO!$O$2:$O$151,MATCH(1*10+5,MOTOR_RELATORIO!$AE$2:$AE$151,0)),"") | H19: =IFERROR(INDEX(MOTOR_RELATORIO!$R$2:$R$151,MATCH(1*10+5,MOTOR_RELATORIO!$AE$2:$AE$151,0)),"") | I19: =IFERROR(INDEX(MOTOR_RELATORIO!$S$2:$S$151,MATCH(1*10+5,MOTOR_RELATORIO!$AE$2:$AE$151,0)),"") | J19: =IFERROR(INDEX(MOTOR_RELATORIO!$T$2:$T$151,MATCH(1*10+5,MOTOR_RELATORIO!$AE$2:$AE$151,0)),"") | K19: =IFERROR(INDEX(MOTOR_RELATORIO!$U$2:$U$151,MATCH(1*10+5,MOTOR_RELATORIO!$AE$2:$AE$151,0)),"")
C20: =IFERROR(INDEX(MOTOR_RELATORIO!$O$2:$O$151,MATCH(1*10+6,MOTOR_RELATORIO!$AE$2:$AE$151,0)),"") | H20: =IFERROR(INDEX(MOTOR_RELATORIO!$R$2:$R$151,MATCH(1*10+6,MOTOR_RELATORIO!$AE$2:$AE$151,0)),"") | I20: =IFERROR(INDEX(MOTOR_RELATORIO!$S$2:$S$151,MATCH(1*10+6,MOTOR_RELATORIO!$AE$2:$AE$151,0)),"") | J20: =IFERROR(INDEX(MOTOR_RELATORIO!$T$2:$T$151,MATCH(1*10+6,MOTOR_RELATORIO!$AE$2:$AE$151,0)),"") | K20: =IFERROR(INDEX(MOTOR_RELATORIO!$U$2:$U$151,MATCH(1*10+6,MOTOR_RELATORIO!$AE$2:$AE$151,0)),"")
G21: RESULTADO: | I21: =IFERROR(INDEX(MOTOR_RELATORIO!$AF$2:$AF$151,MATCH(1*10+1,MOTOR_RELATORIO!$AE$2:$AE$151,0)),"")
G22: VALOR: | I22: =IFERROR(INDEX(MOTOR_RELATORIO!$AG$2:$AG$151,MATCH(1*10+1,MOTOR_RELATORIO!$AE$2:$AE$151,0)),"")
A23: =IFERROR(INDEX(MOTOR_RELATORIO!$Y$2:$Y$151,MATCH(2*10+1,MOTOR_RELATORIO!$AE$2:$AE$151,0)),"") | B23: =IFERROR(INDEX(MOTOR_RELATORIO!$Z$2:$Z$151,MATCH(2*10+1,MOTOR_RELATORIO!$AE$2:$AE$151,0)),"")
A24: =IFERROR(INDEX(MOTOR_RELATORIO!$AA$2:$AA$151,MATCH(2*10+1,MOTOR_RELATORIO!$AE$2:$AE$151,0)),"") | B24: =IFERROR(INDEX(MOTOR_RELATORIO!$AB$2:$AB$151,MATCH(2*10+1,MOTOR_RELATORIO!$AE$2:$AE$151,0)),"")
A25: ITEM | B25: LINHA | C25: DESCRICAO | E25: ATIVIDADE | G25: UND. | H25: X | I25: Y | J25: Z | K25: RESULTADO
A26: =IFERROR(INDEX(MOTOR_RELATORIO!$L$2:$L$151,MATCH(2*10+1,MOTOR_RELATORIO!$AE$2:$AE$151,0)),"") | B26: =IFERROR(INDEX(MOTOR_RELATORIO!$M$2:$M$151,MATCH(2*10+1,MOTOR_RELATORIO!$AE$2:$AE$151,0)),"") | E26: =IFERROR(INDEX(MOTOR_RELATORIO!$N$2:$N$151,MATCH(2*10+1,MOTOR_RELATORIO!$AE$2:$AE$151,0)),"") | G26: =IFERROR(INDEX(MOTOR_RELATORIO!$P$2:$P$151,MATCH(2*10+1,MOTOR_RELATORIO!$AE$2:$AE$151,0)),"")
C27: =IFERROR(INDEX(MOTOR_RELATORIO!$O$2:$O$151,MATCH(2*10+1,MOTOR_RELATORIO!$AE$2:$AE$151,0)),"") | H27: =IFERROR(INDEX(MOTOR_RELATORIO!$R$2:$R$151,MATCH(2*10+1,MOTOR_RELATORIO!$AE$2:$AE$151,0)),"") | I27: =IFERROR(INDEX(MOTOR_RELATORIO!$S$2:$S$151,MATCH(2*10+1,MOTOR_RELATORIO!$AE$2:$AE$151,0)),"") | J27: =IFERROR(INDEX(MOTOR_RELATORIO!$T$2:$T$151,MATCH(2*10+1,MOTOR_RELATORIO!$AE$2:$AE$151,0)),"") | K27: =IFERROR(INDEX(MOTOR_RELATORIO!$U$2:$U$151,MATCH(2*10+1,MOTOR_RELATORIO!$AE$2:$AE$151,0)),"")
